[2024-07-29T00:00:07.050+0000] {processor.py:161} INFO - Started process (PID=4284) to work on /opt/airflow/dags/airflow-dags/datalake/etl_products.py
[2024-07-29T00:00:07.051+0000] {processor.py:830} INFO - Processing file /opt/airflow/dags/airflow-dags/datalake/etl_products.py for tasks to queue
[2024-07-29T00:00:07.052+0000] {logging_mixin.py:188} INFO - [2024-07-29T00:00:07.052+0000] {dagbag.py:540} INFO - Filling up the DagBag from /opt/airflow/dags/airflow-dags/datalake/etl_products.py
[2024-07-29T00:00:08.089+0000] {logging_mixin.py:188} INFO - [2024-07-29T00:00:08.087+0000] {dagbag.py:350} ERROR - Failed to import: /opt/airflow/dags/airflow-dags/datalake/etl_products.py
Traceback (most recent call last):
  File "/home/airflow/.local/lib/python3.12/site-packages/airflow/models/dagbag.py", line 346, in parse
    loader.exec_module(new_module)
  File "<frozen importlib._bootstrap_external>", line 995, in exec_module
  File "<frozen importlib._bootstrap>", line 488, in _call_with_frames_removed
  File "/opt/airflow/dags/airflow-dags/datalake/etl_products.py", line 25, in <module>
    driver = webdriver.Chrome(executable_path=r'/opt/airflow/chromedriver', options=options)
             ^^^^^^^^^^^^^^^^^^^^^^^^^^^^^^^^^^^^^^^^^^^^^^^^^^^^^^^^^^^^^^^^^^^^^^^^^^^^^^^
  File "/home/airflow/.local/lib/python3.12/site-packages/selenium/webdriver/chrome/webdriver.py", line 73, in __init__
    self.service.start()
  File "/home/airflow/.local/lib/python3.12/site-packages/selenium/webdriver/common/service.py", line 98, in start
    self.assert_process_still_running()
  File "/home/airflow/.local/lib/python3.12/site-packages/selenium/webdriver/common/service.py", line 109, in assert_process_still_running
    raise WebDriverException(
selenium.common.exceptions.WebDriverException: Message: Service /opt/airflow/chromedriver unexpectedly exited. Status code was: 127
[2024-07-29T00:00:08.114+0000] {processor.py:842} WARNING - No viable dags retrieved from /opt/airflow/dags/airflow-dags/datalake/etl_products.py
[2024-07-29T00:00:08.128+0000] {processor.py:183} INFO - Processing /opt/airflow/dags/airflow-dags/datalake/etl_products.py took 1.082 seconds
[2024-07-29T00:00:38.272+0000] {processor.py:161} INFO - Started process (PID=4302) to work on /opt/airflow/dags/airflow-dags/datalake/etl_products.py
[2024-07-29T00:00:38.276+0000] {processor.py:830} INFO - Processing file /opt/airflow/dags/airflow-dags/datalake/etl_products.py for tasks to queue
[2024-07-29T00:00:38.278+0000] {logging_mixin.py:188} INFO - [2024-07-29T00:00:38.278+0000] {dagbag.py:540} INFO - Filling up the DagBag from /opt/airflow/dags/airflow-dags/datalake/etl_products.py
[2024-07-29T00:00:39.314+0000] {logging_mixin.py:188} INFO - [2024-07-29T00:00:39.311+0000] {dagbag.py:350} ERROR - Failed to import: /opt/airflow/dags/airflow-dags/datalake/etl_products.py
Traceback (most recent call last):
  File "/home/airflow/.local/lib/python3.12/site-packages/airflow/models/dagbag.py", line 346, in parse
    loader.exec_module(new_module)
  File "<frozen importlib._bootstrap_external>", line 995, in exec_module
  File "<frozen importlib._bootstrap>", line 488, in _call_with_frames_removed
  File "/opt/airflow/dags/airflow-dags/datalake/etl_products.py", line 25, in <module>
    driver = webdriver.Chrome(executable_path=r'/opt/airflow/chromedriver', options=options)
             ^^^^^^^^^^^^^^^^^^^^^^^^^^^^^^^^^^^^^^^^^^^^^^^^^^^^^^^^^^^^^^^^^^^^^^^^^^^^^^^
  File "/home/airflow/.local/lib/python3.12/site-packages/selenium/webdriver/chrome/webdriver.py", line 73, in __init__
    self.service.start()
  File "/home/airflow/.local/lib/python3.12/site-packages/selenium/webdriver/common/service.py", line 98, in start
    self.assert_process_still_running()
  File "/home/airflow/.local/lib/python3.12/site-packages/selenium/webdriver/common/service.py", line 109, in assert_process_still_running
    raise WebDriverException(
selenium.common.exceptions.WebDriverException: Message: Service /opt/airflow/chromedriver unexpectedly exited. Status code was: 127
[2024-07-29T00:00:39.343+0000] {processor.py:842} WARNING - No viable dags retrieved from /opt/airflow/dags/airflow-dags/datalake/etl_products.py
[2024-07-29T00:00:39.359+0000] {processor.py:183} INFO - Processing /opt/airflow/dags/airflow-dags/datalake/etl_products.py took 1.092 seconds
[2024-07-29T00:01:09.538+0000] {processor.py:161} INFO - Started process (PID=4320) to work on /opt/airflow/dags/airflow-dags/datalake/etl_products.py
[2024-07-29T00:01:09.539+0000] {processor.py:830} INFO - Processing file /opt/airflow/dags/airflow-dags/datalake/etl_products.py for tasks to queue
[2024-07-29T00:01:09.540+0000] {logging_mixin.py:188} INFO - [2024-07-29T00:01:09.539+0000] {dagbag.py:540} INFO - Filling up the DagBag from /opt/airflow/dags/airflow-dags/datalake/etl_products.py
[2024-07-29T00:01:10.573+0000] {logging_mixin.py:188} INFO - [2024-07-29T00:01:10.570+0000] {dagbag.py:350} ERROR - Failed to import: /opt/airflow/dags/airflow-dags/datalake/etl_products.py
Traceback (most recent call last):
  File "/home/airflow/.local/lib/python3.12/site-packages/airflow/models/dagbag.py", line 346, in parse
    loader.exec_module(new_module)
  File "<frozen importlib._bootstrap_external>", line 995, in exec_module
  File "<frozen importlib._bootstrap>", line 488, in _call_with_frames_removed
  File "/opt/airflow/dags/airflow-dags/datalake/etl_products.py", line 25, in <module>
    driver = webdriver.Chrome(executable_path=r'/opt/airflow/chromedriver', options=options)
             ^^^^^^^^^^^^^^^^^^^^^^^^^^^^^^^^^^^^^^^^^^^^^^^^^^^^^^^^^^^^^^^^^^^^^^^^^^^^^^^
  File "/home/airflow/.local/lib/python3.12/site-packages/selenium/webdriver/chrome/webdriver.py", line 73, in __init__
    self.service.start()
  File "/home/airflow/.local/lib/python3.12/site-packages/selenium/webdriver/common/service.py", line 98, in start
    self.assert_process_still_running()
  File "/home/airflow/.local/lib/python3.12/site-packages/selenium/webdriver/common/service.py", line 109, in assert_process_still_running
    raise WebDriverException(
selenium.common.exceptions.WebDriverException: Message: Service /opt/airflow/chromedriver unexpectedly exited. Status code was: 127
[2024-07-29T00:01:10.603+0000] {processor.py:842} WARNING - No viable dags retrieved from /opt/airflow/dags/airflow-dags/datalake/etl_products.py
[2024-07-29T00:01:10.619+0000] {processor.py:183} INFO - Processing /opt/airflow/dags/airflow-dags/datalake/etl_products.py took 1.086 seconds
[2024-07-29T00:01:40.802+0000] {processor.py:161} INFO - Started process (PID=4338) to work on /opt/airflow/dags/airflow-dags/datalake/etl_products.py
[2024-07-29T00:01:40.803+0000] {processor.py:830} INFO - Processing file /opt/airflow/dags/airflow-dags/datalake/etl_products.py for tasks to queue
[2024-07-29T00:01:40.804+0000] {logging_mixin.py:188} INFO - [2024-07-29T00:01:40.804+0000] {dagbag.py:540} INFO - Filling up the DagBag from /opt/airflow/dags/airflow-dags/datalake/etl_products.py
[2024-07-29T00:01:41.838+0000] {logging_mixin.py:188} INFO - [2024-07-29T00:01:41.836+0000] {dagbag.py:350} ERROR - Failed to import: /opt/airflow/dags/airflow-dags/datalake/etl_products.py
Traceback (most recent call last):
  File "/home/airflow/.local/lib/python3.12/site-packages/airflow/models/dagbag.py", line 346, in parse
    loader.exec_module(new_module)
  File "<frozen importlib._bootstrap_external>", line 995, in exec_module
  File "<frozen importlib._bootstrap>", line 488, in _call_with_frames_removed
  File "/opt/airflow/dags/airflow-dags/datalake/etl_products.py", line 25, in <module>
    driver = webdriver.Chrome(executable_path=r'/opt/airflow/chromedriver', options=options)
             ^^^^^^^^^^^^^^^^^^^^^^^^^^^^^^^^^^^^^^^^^^^^^^^^^^^^^^^^^^^^^^^^^^^^^^^^^^^^^^^
  File "/home/airflow/.local/lib/python3.12/site-packages/selenium/webdriver/chrome/webdriver.py", line 73, in __init__
    self.service.start()
  File "/home/airflow/.local/lib/python3.12/site-packages/selenium/webdriver/common/service.py", line 98, in start
    self.assert_process_still_running()
  File "/home/airflow/.local/lib/python3.12/site-packages/selenium/webdriver/common/service.py", line 109, in assert_process_still_running
    raise WebDriverException(
selenium.common.exceptions.WebDriverException: Message: Service /opt/airflow/chromedriver unexpectedly exited. Status code was: 127
[2024-07-29T00:01:41.864+0000] {processor.py:842} WARNING - No viable dags retrieved from /opt/airflow/dags/airflow-dags/datalake/etl_products.py
[2024-07-29T00:01:41.877+0000] {processor.py:183} INFO - Processing /opt/airflow/dags/airflow-dags/datalake/etl_products.py took 1.079 seconds
[2024-07-29T00:02:12.074+0000] {processor.py:161} INFO - Started process (PID=4356) to work on /opt/airflow/dags/airflow-dags/datalake/etl_products.py
[2024-07-29T00:02:12.075+0000] {processor.py:830} INFO - Processing file /opt/airflow/dags/airflow-dags/datalake/etl_products.py for tasks to queue
[2024-07-29T00:02:12.076+0000] {logging_mixin.py:188} INFO - [2024-07-29T00:02:12.076+0000] {dagbag.py:540} INFO - Filling up the DagBag from /opt/airflow/dags/airflow-dags/datalake/etl_products.py
[2024-07-29T00:02:13.116+0000] {logging_mixin.py:188} INFO - [2024-07-29T00:02:13.112+0000] {dagbag.py:350} ERROR - Failed to import: /opt/airflow/dags/airflow-dags/datalake/etl_products.py
Traceback (most recent call last):
  File "/home/airflow/.local/lib/python3.12/site-packages/airflow/models/dagbag.py", line 346, in parse
    loader.exec_module(new_module)
  File "<frozen importlib._bootstrap_external>", line 995, in exec_module
  File "<frozen importlib._bootstrap>", line 488, in _call_with_frames_removed
  File "/opt/airflow/dags/airflow-dags/datalake/etl_products.py", line 25, in <module>
    driver = webdriver.Chrome(executable_path=r'/opt/airflow/chromedriver', options=options)
             ^^^^^^^^^^^^^^^^^^^^^^^^^^^^^^^^^^^^^^^^^^^^^^^^^^^^^^^^^^^^^^^^^^^^^^^^^^^^^^^
  File "/home/airflow/.local/lib/python3.12/site-packages/selenium/webdriver/chrome/webdriver.py", line 73, in __init__
    self.service.start()
  File "/home/airflow/.local/lib/python3.12/site-packages/selenium/webdriver/common/service.py", line 98, in start
    self.assert_process_still_running()
  File "/home/airflow/.local/lib/python3.12/site-packages/selenium/webdriver/common/service.py", line 109, in assert_process_still_running
    raise WebDriverException(
selenium.common.exceptions.WebDriverException: Message: Service /opt/airflow/chromedriver unexpectedly exited. Status code was: 127
[2024-07-29T00:02:13.147+0000] {processor.py:842} WARNING - No viable dags retrieved from /opt/airflow/dags/airflow-dags/datalake/etl_products.py
[2024-07-29T00:02:13.163+0000] {processor.py:183} INFO - Processing /opt/airflow/dags/airflow-dags/datalake/etl_products.py took 1.096 seconds
[2024-07-29T00:02:43.337+0000] {processor.py:161} INFO - Started process (PID=4374) to work on /opt/airflow/dags/airflow-dags/datalake/etl_products.py
[2024-07-29T00:02:43.342+0000] {processor.py:830} INFO - Processing file /opt/airflow/dags/airflow-dags/datalake/etl_products.py for tasks to queue
[2024-07-29T00:02:43.344+0000] {logging_mixin.py:188} INFO - [2024-07-29T00:02:43.344+0000] {dagbag.py:540} INFO - Filling up the DagBag from /opt/airflow/dags/airflow-dags/datalake/etl_products.py
[2024-07-29T00:02:44.378+0000] {logging_mixin.py:188} INFO - [2024-07-29T00:02:44.376+0000] {dagbag.py:350} ERROR - Failed to import: /opt/airflow/dags/airflow-dags/datalake/etl_products.py
Traceback (most recent call last):
  File "/home/airflow/.local/lib/python3.12/site-packages/airflow/models/dagbag.py", line 346, in parse
    loader.exec_module(new_module)
  File "<frozen importlib._bootstrap_external>", line 995, in exec_module
  File "<frozen importlib._bootstrap>", line 488, in _call_with_frames_removed
  File "/opt/airflow/dags/airflow-dags/datalake/etl_products.py", line 25, in <module>
    driver = webdriver.Chrome(executable_path=r'/opt/airflow/chromedriver', options=options)
             ^^^^^^^^^^^^^^^^^^^^^^^^^^^^^^^^^^^^^^^^^^^^^^^^^^^^^^^^^^^^^^^^^^^^^^^^^^^^^^^
  File "/home/airflow/.local/lib/python3.12/site-packages/selenium/webdriver/chrome/webdriver.py", line 73, in __init__
    self.service.start()
  File "/home/airflow/.local/lib/python3.12/site-packages/selenium/webdriver/common/service.py", line 98, in start
    self.assert_process_still_running()
  File "/home/airflow/.local/lib/python3.12/site-packages/selenium/webdriver/common/service.py", line 109, in assert_process_still_running
    raise WebDriverException(
selenium.common.exceptions.WebDriverException: Message: Service /opt/airflow/chromedriver unexpectedly exited. Status code was: 127
[2024-07-29T00:02:44.408+0000] {processor.py:842} WARNING - No viable dags retrieved from /opt/airflow/dags/airflow-dags/datalake/etl_products.py
[2024-07-29T00:02:44.424+0000] {processor.py:183} INFO - Processing /opt/airflow/dags/airflow-dags/datalake/etl_products.py took 1.093 seconds
[2024-07-29T00:03:14.615+0000] {processor.py:161} INFO - Started process (PID=4392) to work on /opt/airflow/dags/airflow-dags/datalake/etl_products.py
[2024-07-29T00:03:14.620+0000] {processor.py:830} INFO - Processing file /opt/airflow/dags/airflow-dags/datalake/etl_products.py for tasks to queue
[2024-07-29T00:03:14.621+0000] {logging_mixin.py:188} INFO - [2024-07-29T00:03:14.621+0000] {dagbag.py:540} INFO - Filling up the DagBag from /opt/airflow/dags/airflow-dags/datalake/etl_products.py
[2024-07-29T00:03:15.655+0000] {logging_mixin.py:188} INFO - [2024-07-29T00:03:15.652+0000] {dagbag.py:350} ERROR - Failed to import: /opt/airflow/dags/airflow-dags/datalake/etl_products.py
Traceback (most recent call last):
  File "/home/airflow/.local/lib/python3.12/site-packages/airflow/models/dagbag.py", line 346, in parse
    loader.exec_module(new_module)
  File "<frozen importlib._bootstrap_external>", line 995, in exec_module
  File "<frozen importlib._bootstrap>", line 488, in _call_with_frames_removed
  File "/opt/airflow/dags/airflow-dags/datalake/etl_products.py", line 25, in <module>
    driver = webdriver.Chrome(executable_path=r'/opt/airflow/chromedriver', options=options)
             ^^^^^^^^^^^^^^^^^^^^^^^^^^^^^^^^^^^^^^^^^^^^^^^^^^^^^^^^^^^^^^^^^^^^^^^^^^^^^^^
  File "/home/airflow/.local/lib/python3.12/site-packages/selenium/webdriver/chrome/webdriver.py", line 73, in __init__
    self.service.start()
  File "/home/airflow/.local/lib/python3.12/site-packages/selenium/webdriver/common/service.py", line 98, in start
    self.assert_process_still_running()
  File "/home/airflow/.local/lib/python3.12/site-packages/selenium/webdriver/common/service.py", line 109, in assert_process_still_running
    raise WebDriverException(
selenium.common.exceptions.WebDriverException: Message: Service /opt/airflow/chromedriver unexpectedly exited. Status code was: 127
[2024-07-29T00:03:15.686+0000] {processor.py:842} WARNING - No viable dags retrieved from /opt/airflow/dags/airflow-dags/datalake/etl_products.py
[2024-07-29T00:03:15.704+0000] {processor.py:183} INFO - Processing /opt/airflow/dags/airflow-dags/datalake/etl_products.py took 1.094 seconds
[2024-07-29T00:03:45.877+0000] {processor.py:161} INFO - Started process (PID=4410) to work on /opt/airflow/dags/airflow-dags/datalake/etl_products.py
[2024-07-29T00:03:45.881+0000] {processor.py:830} INFO - Processing file /opt/airflow/dags/airflow-dags/datalake/etl_products.py for tasks to queue
[2024-07-29T00:03:45.883+0000] {logging_mixin.py:188} INFO - [2024-07-29T00:03:45.882+0000] {dagbag.py:540} INFO - Filling up the DagBag from /opt/airflow/dags/airflow-dags/datalake/etl_products.py
[2024-07-29T00:03:46.916+0000] {logging_mixin.py:188} INFO - [2024-07-29T00:03:46.913+0000] {dagbag.py:350} ERROR - Failed to import: /opt/airflow/dags/airflow-dags/datalake/etl_products.py
Traceback (most recent call last):
  File "/home/airflow/.local/lib/python3.12/site-packages/airflow/models/dagbag.py", line 346, in parse
    loader.exec_module(new_module)
  File "<frozen importlib._bootstrap_external>", line 995, in exec_module
  File "<frozen importlib._bootstrap>", line 488, in _call_with_frames_removed
  File "/opt/airflow/dags/airflow-dags/datalake/etl_products.py", line 25, in <module>
    driver = webdriver.Chrome(executable_path=r'/opt/airflow/chromedriver', options=options)
             ^^^^^^^^^^^^^^^^^^^^^^^^^^^^^^^^^^^^^^^^^^^^^^^^^^^^^^^^^^^^^^^^^^^^^^^^^^^^^^^
  File "/home/airflow/.local/lib/python3.12/site-packages/selenium/webdriver/chrome/webdriver.py", line 73, in __init__
    self.service.start()
  File "/home/airflow/.local/lib/python3.12/site-packages/selenium/webdriver/common/service.py", line 98, in start
    self.assert_process_still_running()
  File "/home/airflow/.local/lib/python3.12/site-packages/selenium/webdriver/common/service.py", line 109, in assert_process_still_running
    raise WebDriverException(
selenium.common.exceptions.WebDriverException: Message: Service /opt/airflow/chromedriver unexpectedly exited. Status code was: 127
[2024-07-29T00:03:46.944+0000] {processor.py:842} WARNING - No viable dags retrieved from /opt/airflow/dags/airflow-dags/datalake/etl_products.py
[2024-07-29T00:03:46.958+0000] {processor.py:183} INFO - Processing /opt/airflow/dags/airflow-dags/datalake/etl_products.py took 1.086 seconds
[2024-07-29T00:04:17.141+0000] {processor.py:161} INFO - Started process (PID=4428) to work on /opt/airflow/dags/airflow-dags/datalake/etl_products.py
[2024-07-29T00:04:17.146+0000] {processor.py:830} INFO - Processing file /opt/airflow/dags/airflow-dags/datalake/etl_products.py for tasks to queue
[2024-07-29T00:04:17.147+0000] {logging_mixin.py:188} INFO - [2024-07-29T00:04:17.147+0000] {dagbag.py:540} INFO - Filling up the DagBag from /opt/airflow/dags/airflow-dags/datalake/etl_products.py
[2024-07-29T00:04:18.179+0000] {logging_mixin.py:188} INFO - [2024-07-29T00:04:18.177+0000] {dagbag.py:350} ERROR - Failed to import: /opt/airflow/dags/airflow-dags/datalake/etl_products.py
Traceback (most recent call last):
  File "/home/airflow/.local/lib/python3.12/site-packages/airflow/models/dagbag.py", line 346, in parse
    loader.exec_module(new_module)
  File "<frozen importlib._bootstrap_external>", line 995, in exec_module
  File "<frozen importlib._bootstrap>", line 488, in _call_with_frames_removed
  File "/opt/airflow/dags/airflow-dags/datalake/etl_products.py", line 25, in <module>
    driver = webdriver.Chrome(executable_path=r'/opt/airflow/chromedriver', options=options)
             ^^^^^^^^^^^^^^^^^^^^^^^^^^^^^^^^^^^^^^^^^^^^^^^^^^^^^^^^^^^^^^^^^^^^^^^^^^^^^^^
  File "/home/airflow/.local/lib/python3.12/site-packages/selenium/webdriver/chrome/webdriver.py", line 73, in __init__
    self.service.start()
  File "/home/airflow/.local/lib/python3.12/site-packages/selenium/webdriver/common/service.py", line 98, in start
    self.assert_process_still_running()
  File "/home/airflow/.local/lib/python3.12/site-packages/selenium/webdriver/common/service.py", line 109, in assert_process_still_running
    raise WebDriverException(
selenium.common.exceptions.WebDriverException: Message: Service /opt/airflow/chromedriver unexpectedly exited. Status code was: 127
[2024-07-29T00:04:18.211+0000] {processor.py:842} WARNING - No viable dags retrieved from /opt/airflow/dags/airflow-dags/datalake/etl_products.py
[2024-07-29T00:04:18.224+0000] {processor.py:183} INFO - Processing /opt/airflow/dags/airflow-dags/datalake/etl_products.py took 1.088 seconds
[2024-07-29T00:04:48.381+0000] {processor.py:161} INFO - Started process (PID=4446) to work on /opt/airflow/dags/airflow-dags/datalake/etl_products.py
[2024-07-29T00:04:48.382+0000] {processor.py:830} INFO - Processing file /opt/airflow/dags/airflow-dags/datalake/etl_products.py for tasks to queue
[2024-07-29T00:04:48.383+0000] {logging_mixin.py:188} INFO - [2024-07-29T00:04:48.383+0000] {dagbag.py:540} INFO - Filling up the DagBag from /opt/airflow/dags/airflow-dags/datalake/etl_products.py
[2024-07-29T00:04:49.418+0000] {logging_mixin.py:188} INFO - [2024-07-29T00:04:49.415+0000] {dagbag.py:350} ERROR - Failed to import: /opt/airflow/dags/airflow-dags/datalake/etl_products.py
Traceback (most recent call last):
  File "/home/airflow/.local/lib/python3.12/site-packages/airflow/models/dagbag.py", line 346, in parse
    loader.exec_module(new_module)
  File "<frozen importlib._bootstrap_external>", line 995, in exec_module
  File "<frozen importlib._bootstrap>", line 488, in _call_with_frames_removed
  File "/opt/airflow/dags/airflow-dags/datalake/etl_products.py", line 25, in <module>
    driver = webdriver.Chrome(executable_path=r'/opt/airflow/chromedriver', options=options)
             ^^^^^^^^^^^^^^^^^^^^^^^^^^^^^^^^^^^^^^^^^^^^^^^^^^^^^^^^^^^^^^^^^^^^^^^^^^^^^^^
  File "/home/airflow/.local/lib/python3.12/site-packages/selenium/webdriver/chrome/webdriver.py", line 73, in __init__
    self.service.start()
  File "/home/airflow/.local/lib/python3.12/site-packages/selenium/webdriver/common/service.py", line 98, in start
    self.assert_process_still_running()
  File "/home/airflow/.local/lib/python3.12/site-packages/selenium/webdriver/common/service.py", line 109, in assert_process_still_running
    raise WebDriverException(
selenium.common.exceptions.WebDriverException: Message: Service /opt/airflow/chromedriver unexpectedly exited. Status code was: 127
[2024-07-29T00:04:49.452+0000] {processor.py:842} WARNING - No viable dags retrieved from /opt/airflow/dags/airflow-dags/datalake/etl_products.py
[2024-07-29T00:04:49.470+0000] {processor.py:183} INFO - Processing /opt/airflow/dags/airflow-dags/datalake/etl_products.py took 1.093 seconds
[2024-07-29T00:05:19.679+0000] {processor.py:161} INFO - Started process (PID=4464) to work on /opt/airflow/dags/airflow-dags/datalake/etl_products.py
[2024-07-29T00:05:19.684+0000] {processor.py:830} INFO - Processing file /opt/airflow/dags/airflow-dags/datalake/etl_products.py for tasks to queue
[2024-07-29T00:05:19.685+0000] {logging_mixin.py:188} INFO - [2024-07-29T00:05:19.685+0000] {dagbag.py:540} INFO - Filling up the DagBag from /opt/airflow/dags/airflow-dags/datalake/etl_products.py
[2024-07-29T00:05:20.725+0000] {logging_mixin.py:188} INFO - [2024-07-29T00:05:20.724+0000] {dagbag.py:350} ERROR - Failed to import: /opt/airflow/dags/airflow-dags/datalake/etl_products.py
Traceback (most recent call last):
  File "/home/airflow/.local/lib/python3.12/site-packages/airflow/models/dagbag.py", line 346, in parse
    loader.exec_module(new_module)
  File "<frozen importlib._bootstrap_external>", line 995, in exec_module
  File "<frozen importlib._bootstrap>", line 488, in _call_with_frames_removed
  File "/opt/airflow/dags/airflow-dags/datalake/etl_products.py", line 25, in <module>
    driver = webdriver.Chrome(executable_path=r'/opt/airflow/chromedriver', options=options)
             ^^^^^^^^^^^^^^^^^^^^^^^^^^^^^^^^^^^^^^^^^^^^^^^^^^^^^^^^^^^^^^^^^^^^^^^^^^^^^^^
  File "/home/airflow/.local/lib/python3.12/site-packages/selenium/webdriver/chrome/webdriver.py", line 73, in __init__
    self.service.start()
  File "/home/airflow/.local/lib/python3.12/site-packages/selenium/webdriver/common/service.py", line 98, in start
    self.assert_process_still_running()
  File "/home/airflow/.local/lib/python3.12/site-packages/selenium/webdriver/common/service.py", line 109, in assert_process_still_running
    raise WebDriverException(
selenium.common.exceptions.WebDriverException: Message: Service /opt/airflow/chromedriver unexpectedly exited. Status code was: 127
[2024-07-29T00:05:20.753+0000] {processor.py:842} WARNING - No viable dags retrieved from /opt/airflow/dags/airflow-dags/datalake/etl_products.py
[2024-07-29T00:05:20.769+0000] {processor.py:183} INFO - Processing /opt/airflow/dags/airflow-dags/datalake/etl_products.py took 1.096 seconds
[2024-07-29T00:05:50.935+0000] {processor.py:161} INFO - Started process (PID=4482) to work on /opt/airflow/dags/airflow-dags/datalake/etl_products.py
[2024-07-29T00:05:50.936+0000] {processor.py:830} INFO - Processing file /opt/airflow/dags/airflow-dags/datalake/etl_products.py for tasks to queue
[2024-07-29T00:05:50.937+0000] {logging_mixin.py:188} INFO - [2024-07-29T00:05:50.937+0000] {dagbag.py:540} INFO - Filling up the DagBag from /opt/airflow/dags/airflow-dags/datalake/etl_products.py
[2024-07-29T00:05:51.976+0000] {logging_mixin.py:188} INFO - [2024-07-29T00:05:51.975+0000] {dagbag.py:350} ERROR - Failed to import: /opt/airflow/dags/airflow-dags/datalake/etl_products.py
Traceback (most recent call last):
  File "/home/airflow/.local/lib/python3.12/site-packages/airflow/models/dagbag.py", line 346, in parse
    loader.exec_module(new_module)
  File "<frozen importlib._bootstrap_external>", line 995, in exec_module
  File "<frozen importlib._bootstrap>", line 488, in _call_with_frames_removed
  File "/opt/airflow/dags/airflow-dags/datalake/etl_products.py", line 25, in <module>
    driver = webdriver.Chrome(executable_path=r'/opt/airflow/chromedriver', options=options)
             ^^^^^^^^^^^^^^^^^^^^^^^^^^^^^^^^^^^^^^^^^^^^^^^^^^^^^^^^^^^^^^^^^^^^^^^^^^^^^^^
  File "/home/airflow/.local/lib/python3.12/site-packages/selenium/webdriver/chrome/webdriver.py", line 73, in __init__
    self.service.start()
  File "/home/airflow/.local/lib/python3.12/site-packages/selenium/webdriver/common/service.py", line 98, in start
    self.assert_process_still_running()
  File "/home/airflow/.local/lib/python3.12/site-packages/selenium/webdriver/common/service.py", line 109, in assert_process_still_running
    raise WebDriverException(
selenium.common.exceptions.WebDriverException: Message: Service /opt/airflow/chromedriver unexpectedly exited. Status code was: 127
[2024-07-29T00:05:52.004+0000] {processor.py:842} WARNING - No viable dags retrieved from /opt/airflow/dags/airflow-dags/datalake/etl_products.py
[2024-07-29T00:05:52.020+0000] {processor.py:183} INFO - Processing /opt/airflow/dags/airflow-dags/datalake/etl_products.py took 1.089 seconds
[2024-07-29T00:06:22.199+0000] {processor.py:161} INFO - Started process (PID=4500) to work on /opt/airflow/dags/airflow-dags/datalake/etl_products.py
[2024-07-29T00:06:22.203+0000] {processor.py:830} INFO - Processing file /opt/airflow/dags/airflow-dags/datalake/etl_products.py for tasks to queue
[2024-07-29T00:06:22.204+0000] {logging_mixin.py:188} INFO - [2024-07-29T00:06:22.204+0000] {dagbag.py:540} INFO - Filling up the DagBag from /opt/airflow/dags/airflow-dags/datalake/etl_products.py
[2024-07-29T00:06:23.241+0000] {logging_mixin.py:188} INFO - [2024-07-29T00:06:23.237+0000] {dagbag.py:350} ERROR - Failed to import: /opt/airflow/dags/airflow-dags/datalake/etl_products.py
Traceback (most recent call last):
  File "/home/airflow/.local/lib/python3.12/site-packages/airflow/models/dagbag.py", line 346, in parse
    loader.exec_module(new_module)
  File "<frozen importlib._bootstrap_external>", line 995, in exec_module
  File "<frozen importlib._bootstrap>", line 488, in _call_with_frames_removed
  File "/opt/airflow/dags/airflow-dags/datalake/etl_products.py", line 25, in <module>
    driver = webdriver.Chrome(executable_path=r'/opt/airflow/chromedriver', options=options)
             ^^^^^^^^^^^^^^^^^^^^^^^^^^^^^^^^^^^^^^^^^^^^^^^^^^^^^^^^^^^^^^^^^^^^^^^^^^^^^^^
  File "/home/airflow/.local/lib/python3.12/site-packages/selenium/webdriver/chrome/webdriver.py", line 73, in __init__
    self.service.start()
  File "/home/airflow/.local/lib/python3.12/site-packages/selenium/webdriver/common/service.py", line 98, in start
    self.assert_process_still_running()
  File "/home/airflow/.local/lib/python3.12/site-packages/selenium/webdriver/common/service.py", line 109, in assert_process_still_running
    raise WebDriverException(
selenium.common.exceptions.WebDriverException: Message: Service /opt/airflow/chromedriver unexpectedly exited. Status code was: 127
[2024-07-29T00:06:23.280+0000] {processor.py:842} WARNING - No viable dags retrieved from /opt/airflow/dags/airflow-dags/datalake/etl_products.py
[2024-07-29T00:06:23.295+0000] {processor.py:183} INFO - Processing /opt/airflow/dags/airflow-dags/datalake/etl_products.py took 1.101 seconds
[2024-07-29T00:06:53.470+0000] {processor.py:161} INFO - Started process (PID=4518) to work on /opt/airflow/dags/airflow-dags/datalake/etl_products.py
[2024-07-29T00:06:53.475+0000] {processor.py:830} INFO - Processing file /opt/airflow/dags/airflow-dags/datalake/etl_products.py for tasks to queue
[2024-07-29T00:06:53.476+0000] {logging_mixin.py:188} INFO - [2024-07-29T00:06:53.476+0000] {dagbag.py:540} INFO - Filling up the DagBag from /opt/airflow/dags/airflow-dags/datalake/etl_products.py
[2024-07-29T00:06:54.531+0000] {logging_mixin.py:188} INFO - [2024-07-29T00:06:54.529+0000] {dagbag.py:350} ERROR - Failed to import: /opt/airflow/dags/airflow-dags/datalake/etl_products.py
Traceback (most recent call last):
  File "/home/airflow/.local/lib/python3.12/site-packages/airflow/models/dagbag.py", line 346, in parse
    loader.exec_module(new_module)
  File "<frozen importlib._bootstrap_external>", line 995, in exec_module
  File "<frozen importlib._bootstrap>", line 488, in _call_with_frames_removed
  File "/opt/airflow/dags/airflow-dags/datalake/etl_products.py", line 25, in <module>
    driver = webdriver.Chrome(executable_path=r'/opt/airflow/chromedriver', options=options)
             ^^^^^^^^^^^^^^^^^^^^^^^^^^^^^^^^^^^^^^^^^^^^^^^^^^^^^^^^^^^^^^^^^^^^^^^^^^^^^^^
  File "/home/airflow/.local/lib/python3.12/site-packages/selenium/webdriver/chrome/webdriver.py", line 73, in __init__
    self.service.start()
  File "/home/airflow/.local/lib/python3.12/site-packages/selenium/webdriver/common/service.py", line 98, in start
    self.assert_process_still_running()
  File "/home/airflow/.local/lib/python3.12/site-packages/selenium/webdriver/common/service.py", line 109, in assert_process_still_running
    raise WebDriverException(
selenium.common.exceptions.WebDriverException: Message: Service /opt/airflow/chromedriver unexpectedly exited. Status code was: 127
[2024-07-29T00:06:54.560+0000] {processor.py:842} WARNING - No viable dags retrieved from /opt/airflow/dags/airflow-dags/datalake/etl_products.py
[2024-07-29T00:06:54.580+0000] {processor.py:183} INFO - Processing /opt/airflow/dags/airflow-dags/datalake/etl_products.py took 1.115 seconds
[2024-07-29T00:07:24.769+0000] {processor.py:161} INFO - Started process (PID=4536) to work on /opt/airflow/dags/airflow-dags/datalake/etl_products.py
[2024-07-29T00:07:24.774+0000] {processor.py:830} INFO - Processing file /opt/airflow/dags/airflow-dags/datalake/etl_products.py for tasks to queue
[2024-07-29T00:07:24.775+0000] {logging_mixin.py:188} INFO - [2024-07-29T00:07:24.775+0000] {dagbag.py:540} INFO - Filling up the DagBag from /opt/airflow/dags/airflow-dags/datalake/etl_products.py
[2024-07-29T00:07:25.813+0000] {logging_mixin.py:188} INFO - [2024-07-29T00:07:25.810+0000] {dagbag.py:350} ERROR - Failed to import: /opt/airflow/dags/airflow-dags/datalake/etl_products.py
Traceback (most recent call last):
  File "/home/airflow/.local/lib/python3.12/site-packages/airflow/models/dagbag.py", line 346, in parse
    loader.exec_module(new_module)
  File "<frozen importlib._bootstrap_external>", line 995, in exec_module
  File "<frozen importlib._bootstrap>", line 488, in _call_with_frames_removed
  File "/opt/airflow/dags/airflow-dags/datalake/etl_products.py", line 25, in <module>
    driver = webdriver.Chrome(executable_path=r'/opt/airflow/chromedriver', options=options)
             ^^^^^^^^^^^^^^^^^^^^^^^^^^^^^^^^^^^^^^^^^^^^^^^^^^^^^^^^^^^^^^^^^^^^^^^^^^^^^^^
  File "/home/airflow/.local/lib/python3.12/site-packages/selenium/webdriver/chrome/webdriver.py", line 73, in __init__
    self.service.start()
  File "/home/airflow/.local/lib/python3.12/site-packages/selenium/webdriver/common/service.py", line 98, in start
    self.assert_process_still_running()
  File "/home/airflow/.local/lib/python3.12/site-packages/selenium/webdriver/common/service.py", line 109, in assert_process_still_running
    raise WebDriverException(
selenium.common.exceptions.WebDriverException: Message: Service /opt/airflow/chromedriver unexpectedly exited. Status code was: 127
[2024-07-29T00:07:25.847+0000] {processor.py:842} WARNING - No viable dags retrieved from /opt/airflow/dags/airflow-dags/datalake/etl_products.py
[2024-07-29T00:07:25.867+0000] {processor.py:183} INFO - Processing /opt/airflow/dags/airflow-dags/datalake/etl_products.py took 1.102 seconds
[2024-07-29T00:07:56.057+0000] {processor.py:161} INFO - Started process (PID=4554) to work on /opt/airflow/dags/airflow-dags/datalake/etl_products.py
[2024-07-29T00:07:56.062+0000] {processor.py:830} INFO - Processing file /opt/airflow/dags/airflow-dags/datalake/etl_products.py for tasks to queue
[2024-07-29T00:07:56.064+0000] {logging_mixin.py:188} INFO - [2024-07-29T00:07:56.064+0000] {dagbag.py:540} INFO - Filling up the DagBag from /opt/airflow/dags/airflow-dags/datalake/etl_products.py
[2024-07-29T00:07:57.100+0000] {logging_mixin.py:188} INFO - [2024-07-29T00:07:57.098+0000] {dagbag.py:350} ERROR - Failed to import: /opt/airflow/dags/airflow-dags/datalake/etl_products.py
Traceback (most recent call last):
  File "/home/airflow/.local/lib/python3.12/site-packages/airflow/models/dagbag.py", line 346, in parse
    loader.exec_module(new_module)
  File "<frozen importlib._bootstrap_external>", line 995, in exec_module
  File "<frozen importlib._bootstrap>", line 488, in _call_with_frames_removed
  File "/opt/airflow/dags/airflow-dags/datalake/etl_products.py", line 25, in <module>
    driver = webdriver.Chrome(executable_path=r'/opt/airflow/chromedriver', options=options)
             ^^^^^^^^^^^^^^^^^^^^^^^^^^^^^^^^^^^^^^^^^^^^^^^^^^^^^^^^^^^^^^^^^^^^^^^^^^^^^^^
  File "/home/airflow/.local/lib/python3.12/site-packages/selenium/webdriver/chrome/webdriver.py", line 73, in __init__
    self.service.start()
  File "/home/airflow/.local/lib/python3.12/site-packages/selenium/webdriver/common/service.py", line 98, in start
    self.assert_process_still_running()
  File "/home/airflow/.local/lib/python3.12/site-packages/selenium/webdriver/common/service.py", line 109, in assert_process_still_running
    raise WebDriverException(
selenium.common.exceptions.WebDriverException: Message: Service /opt/airflow/chromedriver unexpectedly exited. Status code was: 127
[2024-07-29T00:07:57.128+0000] {processor.py:842} WARNING - No viable dags retrieved from /opt/airflow/dags/airflow-dags/datalake/etl_products.py
[2024-07-29T00:07:57.142+0000] {processor.py:183} INFO - Processing /opt/airflow/dags/airflow-dags/datalake/etl_products.py took 1.092 seconds
[2024-07-29T00:08:27.338+0000] {processor.py:161} INFO - Started process (PID=4578) to work on /opt/airflow/dags/airflow-dags/datalake/etl_products.py
[2024-07-29T00:08:27.339+0000] {processor.py:830} INFO - Processing file /opt/airflow/dags/airflow-dags/datalake/etl_products.py for tasks to queue
[2024-07-29T00:08:27.341+0000] {logging_mixin.py:188} INFO - [2024-07-29T00:08:27.341+0000] {dagbag.py:540} INFO - Filling up the DagBag from /opt/airflow/dags/airflow-dags/datalake/etl_products.py
[2024-07-29T00:08:28.377+0000] {logging_mixin.py:188} INFO - [2024-07-29T00:08:28.373+0000] {dagbag.py:350} ERROR - Failed to import: /opt/airflow/dags/airflow-dags/datalake/etl_products.py
Traceback (most recent call last):
  File "/home/airflow/.local/lib/python3.12/site-packages/airflow/models/dagbag.py", line 346, in parse
    loader.exec_module(new_module)
  File "<frozen importlib._bootstrap_external>", line 995, in exec_module
  File "<frozen importlib._bootstrap>", line 488, in _call_with_frames_removed
  File "/opt/airflow/dags/airflow-dags/datalake/etl_products.py", line 25, in <module>
    driver = webdriver.Chrome(executable_path=r'/opt/airflow/chromedriver', options=options)
             ^^^^^^^^^^^^^^^^^^^^^^^^^^^^^^^^^^^^^^^^^^^^^^^^^^^^^^^^^^^^^^^^^^^^^^^^^^^^^^^
  File "/home/airflow/.local/lib/python3.12/site-packages/selenium/webdriver/chrome/webdriver.py", line 73, in __init__
    self.service.start()
  File "/home/airflow/.local/lib/python3.12/site-packages/selenium/webdriver/common/service.py", line 98, in start
    self.assert_process_still_running()
  File "/home/airflow/.local/lib/python3.12/site-packages/selenium/webdriver/common/service.py", line 109, in assert_process_still_running
    raise WebDriverException(
selenium.common.exceptions.WebDriverException: Message: Service /opt/airflow/chromedriver unexpectedly exited. Status code was: 127
[2024-07-29T00:08:28.408+0000] {processor.py:842} WARNING - No viable dags retrieved from /opt/airflow/dags/airflow-dags/datalake/etl_products.py
[2024-07-29T00:08:28.425+0000] {processor.py:183} INFO - Processing /opt/airflow/dags/airflow-dags/datalake/etl_products.py took 1.095 seconds
[2024-07-29T00:08:58.634+0000] {processor.py:161} INFO - Started process (PID=4596) to work on /opt/airflow/dags/airflow-dags/datalake/etl_products.py
[2024-07-29T00:08:58.639+0000] {processor.py:830} INFO - Processing file /opt/airflow/dags/airflow-dags/datalake/etl_products.py for tasks to queue
[2024-07-29T00:08:58.640+0000] {logging_mixin.py:188} INFO - [2024-07-29T00:08:58.640+0000] {dagbag.py:540} INFO - Filling up the DagBag from /opt/airflow/dags/airflow-dags/datalake/etl_products.py
[2024-07-29T00:08:59.671+0000] {logging_mixin.py:188} INFO - [2024-07-29T00:08:59.670+0000] {dagbag.py:350} ERROR - Failed to import: /opt/airflow/dags/airflow-dags/datalake/etl_products.py
Traceback (most recent call last):
  File "/home/airflow/.local/lib/python3.12/site-packages/airflow/models/dagbag.py", line 346, in parse
    loader.exec_module(new_module)
  File "<frozen importlib._bootstrap_external>", line 995, in exec_module
  File "<frozen importlib._bootstrap>", line 488, in _call_with_frames_removed
  File "/opt/airflow/dags/airflow-dags/datalake/etl_products.py", line 25, in <module>
    driver = webdriver.Chrome(executable_path=r'/opt/airflow/chromedriver', options=options)
             ^^^^^^^^^^^^^^^^^^^^^^^^^^^^^^^^^^^^^^^^^^^^^^^^^^^^^^^^^^^^^^^^^^^^^^^^^^^^^^^
  File "/home/airflow/.local/lib/python3.12/site-packages/selenium/webdriver/chrome/webdriver.py", line 73, in __init__
    self.service.start()
  File "/home/airflow/.local/lib/python3.12/site-packages/selenium/webdriver/common/service.py", line 98, in start
    self.assert_process_still_running()
  File "/home/airflow/.local/lib/python3.12/site-packages/selenium/webdriver/common/service.py", line 109, in assert_process_still_running
    raise WebDriverException(
selenium.common.exceptions.WebDriverException: Message: Service /opt/airflow/chromedriver unexpectedly exited. Status code was: 127
[2024-07-29T00:08:59.695+0000] {processor.py:842} WARNING - No viable dags retrieved from /opt/airflow/dags/airflow-dags/datalake/etl_products.py
[2024-07-29T00:08:59.709+0000] {processor.py:183} INFO - Processing /opt/airflow/dags/airflow-dags/datalake/etl_products.py took 1.079 seconds
[2024-07-29T00:09:29.896+0000] {processor.py:161} INFO - Started process (PID=4613) to work on /opt/airflow/dags/airflow-dags/datalake/etl_products.py
[2024-07-29T00:09:29.897+0000] {processor.py:830} INFO - Processing file /opt/airflow/dags/airflow-dags/datalake/etl_products.py for tasks to queue
[2024-07-29T00:09:29.899+0000] {logging_mixin.py:188} INFO - [2024-07-29T00:09:29.898+0000] {dagbag.py:540} INFO - Filling up the DagBag from /opt/airflow/dags/airflow-dags/datalake/etl_products.py
[2024-07-29T00:09:30.935+0000] {logging_mixin.py:188} INFO - [2024-07-29T00:09:30.930+0000] {dagbag.py:350} ERROR - Failed to import: /opt/airflow/dags/airflow-dags/datalake/etl_products.py
Traceback (most recent call last):
  File "/home/airflow/.local/lib/python3.12/site-packages/airflow/models/dagbag.py", line 346, in parse
    loader.exec_module(new_module)
  File "<frozen importlib._bootstrap_external>", line 995, in exec_module
  File "<frozen importlib._bootstrap>", line 488, in _call_with_frames_removed
  File "/opt/airflow/dags/airflow-dags/datalake/etl_products.py", line 25, in <module>
    driver = webdriver.Chrome(executable_path=r'/opt/airflow/chromedriver', options=options)
             ^^^^^^^^^^^^^^^^^^^^^^^^^^^^^^^^^^^^^^^^^^^^^^^^^^^^^^^^^^^^^^^^^^^^^^^^^^^^^^^
  File "/home/airflow/.local/lib/python3.12/site-packages/selenium/webdriver/chrome/webdriver.py", line 73, in __init__
    self.service.start()
  File "/home/airflow/.local/lib/python3.12/site-packages/selenium/webdriver/common/service.py", line 98, in start
    self.assert_process_still_running()
  File "/home/airflow/.local/lib/python3.12/site-packages/selenium/webdriver/common/service.py", line 109, in assert_process_still_running
    raise WebDriverException(
selenium.common.exceptions.WebDriverException: Message: Service /opt/airflow/chromedriver unexpectedly exited. Status code was: 127
[2024-07-29T00:09:30.967+0000] {processor.py:842} WARNING - No viable dags retrieved from /opt/airflow/dags/airflow-dags/datalake/etl_products.py
[2024-07-29T00:09:30.985+0000] {processor.py:183} INFO - Processing /opt/airflow/dags/airflow-dags/datalake/etl_products.py took 1.096 seconds
[2024-07-29T00:10:01.211+0000] {processor.py:161} INFO - Started process (PID=4631) to work on /opt/airflow/dags/airflow-dags/datalake/etl_products.py
[2024-07-29T00:10:01.216+0000] {processor.py:830} INFO - Processing file /opt/airflow/dags/airflow-dags/datalake/etl_products.py for tasks to queue
[2024-07-29T00:10:01.217+0000] {logging_mixin.py:188} INFO - [2024-07-29T00:10:01.217+0000] {dagbag.py:540} INFO - Filling up the DagBag from /opt/airflow/dags/airflow-dags/datalake/etl_products.py
[2024-07-29T00:10:02.251+0000] {logging_mixin.py:188} INFO - [2024-07-29T00:10:02.247+0000] {dagbag.py:350} ERROR - Failed to import: /opt/airflow/dags/airflow-dags/datalake/etl_products.py
Traceback (most recent call last):
  File "/home/airflow/.local/lib/python3.12/site-packages/airflow/models/dagbag.py", line 346, in parse
    loader.exec_module(new_module)
  File "<frozen importlib._bootstrap_external>", line 995, in exec_module
  File "<frozen importlib._bootstrap>", line 488, in _call_with_frames_removed
  File "/opt/airflow/dags/airflow-dags/datalake/etl_products.py", line 25, in <module>
    driver = webdriver.Chrome(executable_path=r'/opt/airflow/chromedriver', options=options)
             ^^^^^^^^^^^^^^^^^^^^^^^^^^^^^^^^^^^^^^^^^^^^^^^^^^^^^^^^^^^^^^^^^^^^^^^^^^^^^^^
  File "/home/airflow/.local/lib/python3.12/site-packages/selenium/webdriver/chrome/webdriver.py", line 73, in __init__
    self.service.start()
  File "/home/airflow/.local/lib/python3.12/site-packages/selenium/webdriver/common/service.py", line 98, in start
    self.assert_process_still_running()
  File "/home/airflow/.local/lib/python3.12/site-packages/selenium/webdriver/common/service.py", line 109, in assert_process_still_running
    raise WebDriverException(
selenium.common.exceptions.WebDriverException: Message: Service /opt/airflow/chromedriver unexpectedly exited. Status code was: 127
[2024-07-29T00:10:02.281+0000] {processor.py:842} WARNING - No viable dags retrieved from /opt/airflow/dags/airflow-dags/datalake/etl_products.py
[2024-07-29T00:10:02.300+0000] {processor.py:183} INFO - Processing /opt/airflow/dags/airflow-dags/datalake/etl_products.py took 1.095 seconds
[2024-07-29T00:10:32.505+0000] {processor.py:161} INFO - Started process (PID=4649) to work on /opt/airflow/dags/airflow-dags/datalake/etl_products.py
[2024-07-29T00:10:32.506+0000] {processor.py:830} INFO - Processing file /opt/airflow/dags/airflow-dags/datalake/etl_products.py for tasks to queue
[2024-07-29T00:10:32.508+0000] {logging_mixin.py:188} INFO - [2024-07-29T00:10:32.507+0000] {dagbag.py:540} INFO - Filling up the DagBag from /opt/airflow/dags/airflow-dags/datalake/etl_products.py
[2024-07-29T00:10:33.541+0000] {logging_mixin.py:188} INFO - [2024-07-29T00:10:33.540+0000] {dagbag.py:350} ERROR - Failed to import: /opt/airflow/dags/airflow-dags/datalake/etl_products.py
Traceback (most recent call last):
  File "/home/airflow/.local/lib/python3.12/site-packages/airflow/models/dagbag.py", line 346, in parse
    loader.exec_module(new_module)
  File "<frozen importlib._bootstrap_external>", line 995, in exec_module
  File "<frozen importlib._bootstrap>", line 488, in _call_with_frames_removed
  File "/opt/airflow/dags/airflow-dags/datalake/etl_products.py", line 25, in <module>
    driver = webdriver.Chrome(executable_path=r'/opt/airflow/chromedriver', options=options)
             ^^^^^^^^^^^^^^^^^^^^^^^^^^^^^^^^^^^^^^^^^^^^^^^^^^^^^^^^^^^^^^^^^^^^^^^^^^^^^^^
  File "/home/airflow/.local/lib/python3.12/site-packages/selenium/webdriver/chrome/webdriver.py", line 73, in __init__
    self.service.start()
  File "/home/airflow/.local/lib/python3.12/site-packages/selenium/webdriver/common/service.py", line 98, in start
    self.assert_process_still_running()
  File "/home/airflow/.local/lib/python3.12/site-packages/selenium/webdriver/common/service.py", line 109, in assert_process_still_running
    raise WebDriverException(
selenium.common.exceptions.WebDriverException: Message: Service /opt/airflow/chromedriver unexpectedly exited. Status code was: 127
[2024-07-29T00:10:33.566+0000] {processor.py:842} WARNING - No viable dags retrieved from /opt/airflow/dags/airflow-dags/datalake/etl_products.py
[2024-07-29T00:10:33.579+0000] {processor.py:183} INFO - Processing /opt/airflow/dags/airflow-dags/datalake/etl_products.py took 1.081 seconds
[2024-07-29T00:11:03.792+0000] {processor.py:161} INFO - Started process (PID=4667) to work on /opt/airflow/dags/airflow-dags/datalake/etl_products.py
[2024-07-29T00:11:03.797+0000] {processor.py:830} INFO - Processing file /opt/airflow/dags/airflow-dags/datalake/etl_products.py for tasks to queue
[2024-07-29T00:11:03.799+0000] {logging_mixin.py:188} INFO - [2024-07-29T00:11:03.798+0000] {dagbag.py:540} INFO - Filling up the DagBag from /opt/airflow/dags/airflow-dags/datalake/etl_products.py
[2024-07-29T00:11:04.834+0000] {logging_mixin.py:188} INFO - [2024-07-29T00:11:04.832+0000] {dagbag.py:350} ERROR - Failed to import: /opt/airflow/dags/airflow-dags/datalake/etl_products.py
Traceback (most recent call last):
  File "/home/airflow/.local/lib/python3.12/site-packages/airflow/models/dagbag.py", line 346, in parse
    loader.exec_module(new_module)
  File "<frozen importlib._bootstrap_external>", line 995, in exec_module
  File "<frozen importlib._bootstrap>", line 488, in _call_with_frames_removed
  File "/opt/airflow/dags/airflow-dags/datalake/etl_products.py", line 25, in <module>
    driver = webdriver.Chrome(executable_path=r'/opt/airflow/chromedriver', options=options)
             ^^^^^^^^^^^^^^^^^^^^^^^^^^^^^^^^^^^^^^^^^^^^^^^^^^^^^^^^^^^^^^^^^^^^^^^^^^^^^^^
  File "/home/airflow/.local/lib/python3.12/site-packages/selenium/webdriver/chrome/webdriver.py", line 73, in __init__
    self.service.start()
  File "/home/airflow/.local/lib/python3.12/site-packages/selenium/webdriver/common/service.py", line 98, in start
    self.assert_process_still_running()
  File "/home/airflow/.local/lib/python3.12/site-packages/selenium/webdriver/common/service.py", line 109, in assert_process_still_running
    raise WebDriverException(
selenium.common.exceptions.WebDriverException: Message: Service /opt/airflow/chromedriver unexpectedly exited. Status code was: 127
[2024-07-29T00:11:04.858+0000] {processor.py:842} WARNING - No viable dags retrieved from /opt/airflow/dags/airflow-dags/datalake/etl_products.py
[2024-07-29T00:11:04.879+0000] {processor.py:183} INFO - Processing /opt/airflow/dags/airflow-dags/datalake/etl_products.py took 1.091 seconds
[2024-07-29T00:11:35.051+0000] {processor.py:161} INFO - Started process (PID=4685) to work on /opt/airflow/dags/airflow-dags/datalake/etl_products.py
[2024-07-29T00:11:35.052+0000] {processor.py:830} INFO - Processing file /opt/airflow/dags/airflow-dags/datalake/etl_products.py for tasks to queue
[2024-07-29T00:11:35.053+0000] {logging_mixin.py:188} INFO - [2024-07-29T00:11:35.053+0000] {dagbag.py:540} INFO - Filling up the DagBag from /opt/airflow/dags/airflow-dags/datalake/etl_products.py
[2024-07-29T00:11:36.087+0000] {logging_mixin.py:188} INFO - [2024-07-29T00:11:36.084+0000] {dagbag.py:350} ERROR - Failed to import: /opt/airflow/dags/airflow-dags/datalake/etl_products.py
Traceback (most recent call last):
  File "/home/airflow/.local/lib/python3.12/site-packages/airflow/models/dagbag.py", line 346, in parse
    loader.exec_module(new_module)
  File "<frozen importlib._bootstrap_external>", line 995, in exec_module
  File "<frozen importlib._bootstrap>", line 488, in _call_with_frames_removed
  File "/opt/airflow/dags/airflow-dags/datalake/etl_products.py", line 25, in <module>
    driver = webdriver.Chrome(executable_path=r'/opt/airflow/chromedriver', options=options)
             ^^^^^^^^^^^^^^^^^^^^^^^^^^^^^^^^^^^^^^^^^^^^^^^^^^^^^^^^^^^^^^^^^^^^^^^^^^^^^^^
  File "/home/airflow/.local/lib/python3.12/site-packages/selenium/webdriver/chrome/webdriver.py", line 73, in __init__
    self.service.start()
  File "/home/airflow/.local/lib/python3.12/site-packages/selenium/webdriver/common/service.py", line 98, in start
    self.assert_process_still_running()
  File "/home/airflow/.local/lib/python3.12/site-packages/selenium/webdriver/common/service.py", line 109, in assert_process_still_running
    raise WebDriverException(
selenium.common.exceptions.WebDriverException: Message: Service /opt/airflow/chromedriver unexpectedly exited. Status code was: 127
[2024-07-29T00:11:36.117+0000] {processor.py:842} WARNING - No viable dags retrieved from /opt/airflow/dags/airflow-dags/datalake/etl_products.py
[2024-07-29T00:11:36.135+0000] {processor.py:183} INFO - Processing /opt/airflow/dags/airflow-dags/datalake/etl_products.py took 1.090 seconds
[2024-07-29T00:12:06.359+0000] {processor.py:161} INFO - Started process (PID=4703) to work on /opt/airflow/dags/airflow-dags/datalake/etl_products.py
[2024-07-29T00:12:06.360+0000] {processor.py:830} INFO - Processing file /opt/airflow/dags/airflow-dags/datalake/etl_products.py for tasks to queue
[2024-07-29T00:12:06.361+0000] {logging_mixin.py:188} INFO - [2024-07-29T00:12:06.361+0000] {dagbag.py:540} INFO - Filling up the DagBag from /opt/airflow/dags/airflow-dags/datalake/etl_products.py
[2024-07-29T00:12:07.398+0000] {logging_mixin.py:188} INFO - [2024-07-29T00:12:07.397+0000] {dagbag.py:350} ERROR - Failed to import: /opt/airflow/dags/airflow-dags/datalake/etl_products.py
Traceback (most recent call last):
  File "/home/airflow/.local/lib/python3.12/site-packages/airflow/models/dagbag.py", line 346, in parse
    loader.exec_module(new_module)
  File "<frozen importlib._bootstrap_external>", line 995, in exec_module
  File "<frozen importlib._bootstrap>", line 488, in _call_with_frames_removed
  File "/opt/airflow/dags/airflow-dags/datalake/etl_products.py", line 25, in <module>
    driver = webdriver.Chrome(executable_path=r'/opt/airflow/chromedriver', options=options)
             ^^^^^^^^^^^^^^^^^^^^^^^^^^^^^^^^^^^^^^^^^^^^^^^^^^^^^^^^^^^^^^^^^^^^^^^^^^^^^^^
  File "/home/airflow/.local/lib/python3.12/site-packages/selenium/webdriver/chrome/webdriver.py", line 73, in __init__
    self.service.start()
  File "/home/airflow/.local/lib/python3.12/site-packages/selenium/webdriver/common/service.py", line 98, in start
    self.assert_process_still_running()
  File "/home/airflow/.local/lib/python3.12/site-packages/selenium/webdriver/common/service.py", line 109, in assert_process_still_running
    raise WebDriverException(
selenium.common.exceptions.WebDriverException: Message: Service /opt/airflow/chromedriver unexpectedly exited. Status code was: 127
[2024-07-29T00:12:07.423+0000] {processor.py:842} WARNING - No viable dags retrieved from /opt/airflow/dags/airflow-dags/datalake/etl_products.py
[2024-07-29T00:12:07.441+0000] {processor.py:183} INFO - Processing /opt/airflow/dags/airflow-dags/datalake/etl_products.py took 1.086 seconds
[2024-07-29T00:12:37.640+0000] {processor.py:161} INFO - Started process (PID=4721) to work on /opt/airflow/dags/airflow-dags/datalake/etl_products.py
[2024-07-29T00:12:37.641+0000] {processor.py:830} INFO - Processing file /opt/airflow/dags/airflow-dags/datalake/etl_products.py for tasks to queue
[2024-07-29T00:12:37.642+0000] {logging_mixin.py:188} INFO - [2024-07-29T00:12:37.642+0000] {dagbag.py:540} INFO - Filling up the DagBag from /opt/airflow/dags/airflow-dags/datalake/etl_products.py
[2024-07-29T00:12:38.676+0000] {logging_mixin.py:188} INFO - [2024-07-29T00:12:38.675+0000] {dagbag.py:350} ERROR - Failed to import: /opt/airflow/dags/airflow-dags/datalake/etl_products.py
Traceback (most recent call last):
  File "/home/airflow/.local/lib/python3.12/site-packages/airflow/models/dagbag.py", line 346, in parse
    loader.exec_module(new_module)
  File "<frozen importlib._bootstrap_external>", line 995, in exec_module
  File "<frozen importlib._bootstrap>", line 488, in _call_with_frames_removed
  File "/opt/airflow/dags/airflow-dags/datalake/etl_products.py", line 25, in <module>
    driver = webdriver.Chrome(executable_path=r'/opt/airflow/chromedriver', options=options)
             ^^^^^^^^^^^^^^^^^^^^^^^^^^^^^^^^^^^^^^^^^^^^^^^^^^^^^^^^^^^^^^^^^^^^^^^^^^^^^^^
  File "/home/airflow/.local/lib/python3.12/site-packages/selenium/webdriver/chrome/webdriver.py", line 73, in __init__
    self.service.start()
  File "/home/airflow/.local/lib/python3.12/site-packages/selenium/webdriver/common/service.py", line 98, in start
    self.assert_process_still_running()
  File "/home/airflow/.local/lib/python3.12/site-packages/selenium/webdriver/common/service.py", line 109, in assert_process_still_running
    raise WebDriverException(
selenium.common.exceptions.WebDriverException: Message: Service /opt/airflow/chromedriver unexpectedly exited. Status code was: 127
[2024-07-29T00:12:38.701+0000] {processor.py:842} WARNING - No viable dags retrieved from /opt/airflow/dags/airflow-dags/datalake/etl_products.py
[2024-07-29T00:12:38.720+0000] {processor.py:183} INFO - Processing /opt/airflow/dags/airflow-dags/datalake/etl_products.py took 1.084 seconds
[2024-07-29T00:13:08.957+0000] {processor.py:161} INFO - Started process (PID=4739) to work on /opt/airflow/dags/airflow-dags/datalake/etl_products.py
[2024-07-29T00:13:08.962+0000] {processor.py:830} INFO - Processing file /opt/airflow/dags/airflow-dags/datalake/etl_products.py for tasks to queue
[2024-07-29T00:13:08.964+0000] {logging_mixin.py:188} INFO - [2024-07-29T00:13:08.964+0000] {dagbag.py:540} INFO - Filling up the DagBag from /opt/airflow/dags/airflow-dags/datalake/etl_products.py
[2024-07-29T00:13:09.998+0000] {logging_mixin.py:188} INFO - [2024-07-29T00:13:09.997+0000] {dagbag.py:350} ERROR - Failed to import: /opt/airflow/dags/airflow-dags/datalake/etl_products.py
Traceback (most recent call last):
  File "/home/airflow/.local/lib/python3.12/site-packages/airflow/models/dagbag.py", line 346, in parse
    loader.exec_module(new_module)
  File "<frozen importlib._bootstrap_external>", line 995, in exec_module
  File "<frozen importlib._bootstrap>", line 488, in _call_with_frames_removed
  File "/opt/airflow/dags/airflow-dags/datalake/etl_products.py", line 25, in <module>
    driver = webdriver.Chrome(executable_path=r'/opt/airflow/chromedriver', options=options)
             ^^^^^^^^^^^^^^^^^^^^^^^^^^^^^^^^^^^^^^^^^^^^^^^^^^^^^^^^^^^^^^^^^^^^^^^^^^^^^^^
  File "/home/airflow/.local/lib/python3.12/site-packages/selenium/webdriver/chrome/webdriver.py", line 73, in __init__
    self.service.start()
  File "/home/airflow/.local/lib/python3.12/site-packages/selenium/webdriver/common/service.py", line 98, in start
    self.assert_process_still_running()
  File "/home/airflow/.local/lib/python3.12/site-packages/selenium/webdriver/common/service.py", line 109, in assert_process_still_running
    raise WebDriverException(
selenium.common.exceptions.WebDriverException: Message: Service /opt/airflow/chromedriver unexpectedly exited. Status code was: 127
[2024-07-29T00:13:10.023+0000] {processor.py:842} WARNING - No viable dags retrieved from /opt/airflow/dags/airflow-dags/datalake/etl_products.py
[2024-07-29T00:13:10.043+0000] {processor.py:183} INFO - Processing /opt/airflow/dags/airflow-dags/datalake/etl_products.py took 1.093 seconds
[2024-07-29T00:13:40.210+0000] {processor.py:161} INFO - Started process (PID=4757) to work on /opt/airflow/dags/airflow-dags/datalake/etl_products.py
[2024-07-29T00:13:40.215+0000] {processor.py:830} INFO - Processing file /opt/airflow/dags/airflow-dags/datalake/etl_products.py for tasks to queue
[2024-07-29T00:13:40.216+0000] {logging_mixin.py:188} INFO - [2024-07-29T00:13:40.216+0000] {dagbag.py:540} INFO - Filling up the DagBag from /opt/airflow/dags/airflow-dags/datalake/etl_products.py
[2024-07-29T00:13:41.248+0000] {logging_mixin.py:188} INFO - [2024-07-29T00:13:41.247+0000] {dagbag.py:350} ERROR - Failed to import: /opt/airflow/dags/airflow-dags/datalake/etl_products.py
Traceback (most recent call last):
  File "/home/airflow/.local/lib/python3.12/site-packages/airflow/models/dagbag.py", line 346, in parse
    loader.exec_module(new_module)
  File "<frozen importlib._bootstrap_external>", line 995, in exec_module
  File "<frozen importlib._bootstrap>", line 488, in _call_with_frames_removed
  File "/opt/airflow/dags/airflow-dags/datalake/etl_products.py", line 25, in <module>
    driver = webdriver.Chrome(executable_path=r'/opt/airflow/chromedriver', options=options)
             ^^^^^^^^^^^^^^^^^^^^^^^^^^^^^^^^^^^^^^^^^^^^^^^^^^^^^^^^^^^^^^^^^^^^^^^^^^^^^^^
  File "/home/airflow/.local/lib/python3.12/site-packages/selenium/webdriver/chrome/webdriver.py", line 73, in __init__
    self.service.start()
  File "/home/airflow/.local/lib/python3.12/site-packages/selenium/webdriver/common/service.py", line 98, in start
    self.assert_process_still_running()
  File "/home/airflow/.local/lib/python3.12/site-packages/selenium/webdriver/common/service.py", line 109, in assert_process_still_running
    raise WebDriverException(
selenium.common.exceptions.WebDriverException: Message: Service /opt/airflow/chromedriver unexpectedly exited. Status code was: 127
[2024-07-29T00:13:41.272+0000] {processor.py:842} WARNING - No viable dags retrieved from /opt/airflow/dags/airflow-dags/datalake/etl_products.py
[2024-07-29T00:13:41.285+0000] {processor.py:183} INFO - Processing /opt/airflow/dags/airflow-dags/datalake/etl_products.py took 1.081 seconds
[2024-07-29T00:14:11.529+0000] {processor.py:161} INFO - Started process (PID=4775) to work on /opt/airflow/dags/airflow-dags/datalake/etl_products.py
[2024-07-29T00:14:11.534+0000] {processor.py:830} INFO - Processing file /opt/airflow/dags/airflow-dags/datalake/etl_products.py for tasks to queue
[2024-07-29T00:14:11.535+0000] {logging_mixin.py:188} INFO - [2024-07-29T00:14:11.535+0000] {dagbag.py:540} INFO - Filling up the DagBag from /opt/airflow/dags/airflow-dags/datalake/etl_products.py
[2024-07-29T00:14:12.573+0000] {logging_mixin.py:188} INFO - [2024-07-29T00:14:12.569+0000] {dagbag.py:350} ERROR - Failed to import: /opt/airflow/dags/airflow-dags/datalake/etl_products.py
Traceback (most recent call last):
  File "/home/airflow/.local/lib/python3.12/site-packages/airflow/models/dagbag.py", line 346, in parse
    loader.exec_module(new_module)
  File "<frozen importlib._bootstrap_external>", line 995, in exec_module
  File "<frozen importlib._bootstrap>", line 488, in _call_with_frames_removed
  File "/opt/airflow/dags/airflow-dags/datalake/etl_products.py", line 25, in <module>
    driver = webdriver.Chrome(executable_path=r'/opt/airflow/chromedriver', options=options)
             ^^^^^^^^^^^^^^^^^^^^^^^^^^^^^^^^^^^^^^^^^^^^^^^^^^^^^^^^^^^^^^^^^^^^^^^^^^^^^^^
  File "/home/airflow/.local/lib/python3.12/site-packages/selenium/webdriver/chrome/webdriver.py", line 73, in __init__
    self.service.start()
  File "/home/airflow/.local/lib/python3.12/site-packages/selenium/webdriver/common/service.py", line 98, in start
    self.assert_process_still_running()
  File "/home/airflow/.local/lib/python3.12/site-packages/selenium/webdriver/common/service.py", line 109, in assert_process_still_running
    raise WebDriverException(
selenium.common.exceptions.WebDriverException: Message: Service /opt/airflow/chromedriver unexpectedly exited. Status code was: 127
[2024-07-29T00:14:12.605+0000] {processor.py:842} WARNING - No viable dags retrieved from /opt/airflow/dags/airflow-dags/datalake/etl_products.py
[2024-07-29T00:14:12.619+0000] {processor.py:183} INFO - Processing /opt/airflow/dags/airflow-dags/datalake/etl_products.py took 1.095 seconds
[2024-07-29T00:14:42.810+0000] {processor.py:161} INFO - Started process (PID=4793) to work on /opt/airflow/dags/airflow-dags/datalake/etl_products.py
[2024-07-29T00:14:42.816+0000] {processor.py:830} INFO - Processing file /opt/airflow/dags/airflow-dags/datalake/etl_products.py for tasks to queue
[2024-07-29T00:14:42.819+0000] {logging_mixin.py:188} INFO - [2024-07-29T00:14:42.818+0000] {dagbag.py:540} INFO - Filling up the DagBag from /opt/airflow/dags/airflow-dags/datalake/etl_products.py
[2024-07-29T00:14:43.865+0000] {logging_mixin.py:188} INFO - [2024-07-29T00:14:43.862+0000] {dagbag.py:350} ERROR - Failed to import: /opt/airflow/dags/airflow-dags/datalake/etl_products.py
Traceback (most recent call last):
  File "/home/airflow/.local/lib/python3.12/site-packages/airflow/models/dagbag.py", line 346, in parse
    loader.exec_module(new_module)
  File "<frozen importlib._bootstrap_external>", line 995, in exec_module
  File "<frozen importlib._bootstrap>", line 488, in _call_with_frames_removed
  File "/opt/airflow/dags/airflow-dags/datalake/etl_products.py", line 25, in <module>
    driver = webdriver.Chrome(executable_path=r'/opt/airflow/chromedriver', options=options)
             ^^^^^^^^^^^^^^^^^^^^^^^^^^^^^^^^^^^^^^^^^^^^^^^^^^^^^^^^^^^^^^^^^^^^^^^^^^^^^^^
  File "/home/airflow/.local/lib/python3.12/site-packages/selenium/webdriver/chrome/webdriver.py", line 73, in __init__
    self.service.start()
  File "/home/airflow/.local/lib/python3.12/site-packages/selenium/webdriver/common/service.py", line 98, in start
    self.assert_process_still_running()
  File "/home/airflow/.local/lib/python3.12/site-packages/selenium/webdriver/common/service.py", line 109, in assert_process_still_running
    raise WebDriverException(
selenium.common.exceptions.WebDriverException: Message: Service /opt/airflow/chromedriver unexpectedly exited. Status code was: 127
[2024-07-29T00:14:43.911+0000] {processor.py:842} WARNING - No viable dags retrieved from /opt/airflow/dags/airflow-dags/datalake/etl_products.py
[2024-07-29T00:14:43.933+0000] {processor.py:183} INFO - Processing /opt/airflow/dags/airflow-dags/datalake/etl_products.py took 1.137 seconds
[2024-07-29T00:15:14.154+0000] {processor.py:161} INFO - Started process (PID=4811) to work on /opt/airflow/dags/airflow-dags/datalake/etl_products.py
[2024-07-29T00:15:14.156+0000] {processor.py:830} INFO - Processing file /opt/airflow/dags/airflow-dags/datalake/etl_products.py for tasks to queue
[2024-07-29T00:15:14.157+0000] {logging_mixin.py:188} INFO - [2024-07-29T00:15:14.157+0000] {dagbag.py:540} INFO - Filling up the DagBag from /opt/airflow/dags/airflow-dags/datalake/etl_products.py
[2024-07-29T00:15:15.199+0000] {logging_mixin.py:188} INFO - [2024-07-29T00:15:15.196+0000] {dagbag.py:350} ERROR - Failed to import: /opt/airflow/dags/airflow-dags/datalake/etl_products.py
Traceback (most recent call last):
  File "/home/airflow/.local/lib/python3.12/site-packages/airflow/models/dagbag.py", line 346, in parse
    loader.exec_module(new_module)
  File "<frozen importlib._bootstrap_external>", line 995, in exec_module
  File "<frozen importlib._bootstrap>", line 488, in _call_with_frames_removed
  File "/opt/airflow/dags/airflow-dags/datalake/etl_products.py", line 25, in <module>
    driver = webdriver.Chrome(executable_path=r'/opt/airflow/chromedriver', options=options)
             ^^^^^^^^^^^^^^^^^^^^^^^^^^^^^^^^^^^^^^^^^^^^^^^^^^^^^^^^^^^^^^^^^^^^^^^^^^^^^^^
  File "/home/airflow/.local/lib/python3.12/site-packages/selenium/webdriver/chrome/webdriver.py", line 73, in __init__
    self.service.start()
  File "/home/airflow/.local/lib/python3.12/site-packages/selenium/webdriver/common/service.py", line 98, in start
    self.assert_process_still_running()
  File "/home/airflow/.local/lib/python3.12/site-packages/selenium/webdriver/common/service.py", line 109, in assert_process_still_running
    raise WebDriverException(
selenium.common.exceptions.WebDriverException: Message: Service /opt/airflow/chromedriver unexpectedly exited. Status code was: 127
[2024-07-29T00:15:15.231+0000] {processor.py:842} WARNING - No viable dags retrieved from /opt/airflow/dags/airflow-dags/datalake/etl_products.py
[2024-07-29T00:15:15.248+0000] {processor.py:183} INFO - Processing /opt/airflow/dags/airflow-dags/datalake/etl_products.py took 1.103 seconds
[2024-07-29T00:15:45.405+0000] {processor.py:161} INFO - Started process (PID=4829) to work on /opt/airflow/dags/airflow-dags/datalake/etl_products.py
[2024-07-29T00:15:45.410+0000] {processor.py:830} INFO - Processing file /opt/airflow/dags/airflow-dags/datalake/etl_products.py for tasks to queue
[2024-07-29T00:15:45.411+0000] {logging_mixin.py:188} INFO - [2024-07-29T00:15:45.411+0000] {dagbag.py:540} INFO - Filling up the DagBag from /opt/airflow/dags/airflow-dags/datalake/etl_products.py
[2024-07-29T00:15:46.455+0000] {logging_mixin.py:188} INFO - [2024-07-29T00:15:46.453+0000] {dagbag.py:350} ERROR - Failed to import: /opt/airflow/dags/airflow-dags/datalake/etl_products.py
Traceback (most recent call last):
  File "/home/airflow/.local/lib/python3.12/site-packages/airflow/models/dagbag.py", line 346, in parse
    loader.exec_module(new_module)
  File "<frozen importlib._bootstrap_external>", line 995, in exec_module
  File "<frozen importlib._bootstrap>", line 488, in _call_with_frames_removed
  File "/opt/airflow/dags/airflow-dags/datalake/etl_products.py", line 25, in <module>
    driver = webdriver.Chrome(executable_path=r'/opt/airflow/chromedriver', options=options)
             ^^^^^^^^^^^^^^^^^^^^^^^^^^^^^^^^^^^^^^^^^^^^^^^^^^^^^^^^^^^^^^^^^^^^^^^^^^^^^^^
  File "/home/airflow/.local/lib/python3.12/site-packages/selenium/webdriver/chrome/webdriver.py", line 73, in __init__
    self.service.start()
  File "/home/airflow/.local/lib/python3.12/site-packages/selenium/webdriver/common/service.py", line 98, in start
    self.assert_process_still_running()
  File "/home/airflow/.local/lib/python3.12/site-packages/selenium/webdriver/common/service.py", line 109, in assert_process_still_running
    raise WebDriverException(
selenium.common.exceptions.WebDriverException: Message: Service /opt/airflow/chromedriver unexpectedly exited. Status code was: 127
[2024-07-29T00:15:46.485+0000] {processor.py:842} WARNING - No viable dags retrieved from /opt/airflow/dags/airflow-dags/datalake/etl_products.py
[2024-07-29T00:15:46.507+0000] {processor.py:183} INFO - Processing /opt/airflow/dags/airflow-dags/datalake/etl_products.py took 1.107 seconds
[2024-07-29T00:16:16.716+0000] {processor.py:161} INFO - Started process (PID=4847) to work on /opt/airflow/dags/airflow-dags/datalake/etl_products.py
[2024-07-29T00:16:16.721+0000] {processor.py:830} INFO - Processing file /opt/airflow/dags/airflow-dags/datalake/etl_products.py for tasks to queue
[2024-07-29T00:16:16.723+0000] {logging_mixin.py:188} INFO - [2024-07-29T00:16:16.722+0000] {dagbag.py:540} INFO - Filling up the DagBag from /opt/airflow/dags/airflow-dags/datalake/etl_products.py
[2024-07-29T00:16:17.757+0000] {logging_mixin.py:188} INFO - [2024-07-29T00:16:17.756+0000] {dagbag.py:350} ERROR - Failed to import: /opt/airflow/dags/airflow-dags/datalake/etl_products.py
Traceback (most recent call last):
  File "/home/airflow/.local/lib/python3.12/site-packages/airflow/models/dagbag.py", line 346, in parse
    loader.exec_module(new_module)
  File "<frozen importlib._bootstrap_external>", line 995, in exec_module
  File "<frozen importlib._bootstrap>", line 488, in _call_with_frames_removed
  File "/opt/airflow/dags/airflow-dags/datalake/etl_products.py", line 25, in <module>
    driver = webdriver.Chrome(executable_path=r'/opt/airflow/chromedriver', options=options)
             ^^^^^^^^^^^^^^^^^^^^^^^^^^^^^^^^^^^^^^^^^^^^^^^^^^^^^^^^^^^^^^^^^^^^^^^^^^^^^^^
  File "/home/airflow/.local/lib/python3.12/site-packages/selenium/webdriver/chrome/webdriver.py", line 73, in __init__
    self.service.start()
  File "/home/airflow/.local/lib/python3.12/site-packages/selenium/webdriver/common/service.py", line 98, in start
    self.assert_process_still_running()
  File "/home/airflow/.local/lib/python3.12/site-packages/selenium/webdriver/common/service.py", line 109, in assert_process_still_running
    raise WebDriverException(
selenium.common.exceptions.WebDriverException: Message: Service /opt/airflow/chromedriver unexpectedly exited. Status code was: 127
[2024-07-29T00:16:17.783+0000] {processor.py:842} WARNING - No viable dags retrieved from /opt/airflow/dags/airflow-dags/datalake/etl_products.py
[2024-07-29T00:16:17.800+0000] {processor.py:183} INFO - Processing /opt/airflow/dags/airflow-dags/datalake/etl_products.py took 1.089 seconds
[2024-07-29T00:16:48.011+0000] {processor.py:161} INFO - Started process (PID=4865) to work on /opt/airflow/dags/airflow-dags/datalake/etl_products.py
[2024-07-29T00:16:48.015+0000] {processor.py:830} INFO - Processing file /opt/airflow/dags/airflow-dags/datalake/etl_products.py for tasks to queue
[2024-07-29T00:16:48.017+0000] {logging_mixin.py:188} INFO - [2024-07-29T00:16:48.016+0000] {dagbag.py:540} INFO - Filling up the DagBag from /opt/airflow/dags/airflow-dags/datalake/etl_products.py
[2024-07-29T00:16:49.052+0000] {logging_mixin.py:188} INFO - [2024-07-29T00:16:49.050+0000] {dagbag.py:350} ERROR - Failed to import: /opt/airflow/dags/airflow-dags/datalake/etl_products.py
Traceback (most recent call last):
  File "/home/airflow/.local/lib/python3.12/site-packages/airflow/models/dagbag.py", line 346, in parse
    loader.exec_module(new_module)
  File "<frozen importlib._bootstrap_external>", line 995, in exec_module
  File "<frozen importlib._bootstrap>", line 488, in _call_with_frames_removed
  File "/opt/airflow/dags/airflow-dags/datalake/etl_products.py", line 25, in <module>
    driver = webdriver.Chrome(executable_path=r'/opt/airflow/chromedriver', options=options)
             ^^^^^^^^^^^^^^^^^^^^^^^^^^^^^^^^^^^^^^^^^^^^^^^^^^^^^^^^^^^^^^^^^^^^^^^^^^^^^^^
  File "/home/airflow/.local/lib/python3.12/site-packages/selenium/webdriver/chrome/webdriver.py", line 73, in __init__
    self.service.start()
  File "/home/airflow/.local/lib/python3.12/site-packages/selenium/webdriver/common/service.py", line 98, in start
    self.assert_process_still_running()
  File "/home/airflow/.local/lib/python3.12/site-packages/selenium/webdriver/common/service.py", line 109, in assert_process_still_running
    raise WebDriverException(
selenium.common.exceptions.WebDriverException: Message: Service /opt/airflow/chromedriver unexpectedly exited. Status code was: 127
[2024-07-29T00:16:49.080+0000] {processor.py:842} WARNING - No viable dags retrieved from /opt/airflow/dags/airflow-dags/datalake/etl_products.py
[2024-07-29T00:16:49.097+0000] {processor.py:183} INFO - Processing /opt/airflow/dags/airflow-dags/datalake/etl_products.py took 1.091 seconds
[2024-07-29T00:17:19.726+0000] {processor.py:161} INFO - Started process (PID=4889) to work on /opt/airflow/dags/airflow-dags/datalake/etl_products.py
[2024-07-29T00:17:19.730+0000] {processor.py:830} INFO - Processing file /opt/airflow/dags/airflow-dags/datalake/etl_products.py for tasks to queue
[2024-07-29T00:17:19.732+0000] {logging_mixin.py:188} INFO - [2024-07-29T00:17:19.732+0000] {dagbag.py:540} INFO - Filling up the DagBag from /opt/airflow/dags/airflow-dags/datalake/etl_products.py
[2024-07-29T00:17:20.767+0000] {logging_mixin.py:188} INFO - [2024-07-29T00:17:20.766+0000] {dagbag.py:350} ERROR - Failed to import: /opt/airflow/dags/airflow-dags/datalake/etl_products.py
Traceback (most recent call last):
  File "/home/airflow/.local/lib/python3.12/site-packages/airflow/models/dagbag.py", line 346, in parse
    loader.exec_module(new_module)
  File "<frozen importlib._bootstrap_external>", line 995, in exec_module
  File "<frozen importlib._bootstrap>", line 488, in _call_with_frames_removed
  File "/opt/airflow/dags/airflow-dags/datalake/etl_products.py", line 25, in <module>
    driver = webdriver.Chrome(executable_path=r'/opt/airflow/chromedriver', options=options)
             ^^^^^^^^^^^^^^^^^^^^^^^^^^^^^^^^^^^^^^^^^^^^^^^^^^^^^^^^^^^^^^^^^^^^^^^^^^^^^^^
  File "/home/airflow/.local/lib/python3.12/site-packages/selenium/webdriver/chrome/webdriver.py", line 73, in __init__
    self.service.start()
  File "/home/airflow/.local/lib/python3.12/site-packages/selenium/webdriver/common/service.py", line 98, in start
    self.assert_process_still_running()
  File "/home/airflow/.local/lib/python3.12/site-packages/selenium/webdriver/common/service.py", line 109, in assert_process_still_running
    raise WebDriverException(
selenium.common.exceptions.WebDriverException: Message: Service /opt/airflow/chromedriver unexpectedly exited. Status code was: 127
[2024-07-29T00:17:20.800+0000] {processor.py:842} WARNING - No viable dags retrieved from /opt/airflow/dags/airflow-dags/datalake/etl_products.py
[2024-07-29T00:17:20.819+0000] {processor.py:183} INFO - Processing /opt/airflow/dags/airflow-dags/datalake/etl_products.py took 1.098 seconds
[2024-07-29T00:17:50.965+0000] {processor.py:161} INFO - Started process (PID=4907) to work on /opt/airflow/dags/airflow-dags/datalake/etl_products.py
[2024-07-29T00:17:50.970+0000] {processor.py:830} INFO - Processing file /opt/airflow/dags/airflow-dags/datalake/etl_products.py for tasks to queue
[2024-07-29T00:17:50.973+0000] {logging_mixin.py:188} INFO - [2024-07-29T00:17:50.973+0000] {dagbag.py:540} INFO - Filling up the DagBag from /opt/airflow/dags/airflow-dags/datalake/etl_products.py
[2024-07-29T00:17:52.012+0000] {logging_mixin.py:188} INFO - [2024-07-29T00:17:52.010+0000] {dagbag.py:350} ERROR - Failed to import: /opt/airflow/dags/airflow-dags/datalake/etl_products.py
Traceback (most recent call last):
  File "/home/airflow/.local/lib/python3.12/site-packages/airflow/models/dagbag.py", line 346, in parse
    loader.exec_module(new_module)
  File "<frozen importlib._bootstrap_external>", line 995, in exec_module
  File "<frozen importlib._bootstrap>", line 488, in _call_with_frames_removed
  File "/opt/airflow/dags/airflow-dags/datalake/etl_products.py", line 25, in <module>
    driver = webdriver.Chrome(executable_path=r'/opt/airflow/chromedriver', options=options)
             ^^^^^^^^^^^^^^^^^^^^^^^^^^^^^^^^^^^^^^^^^^^^^^^^^^^^^^^^^^^^^^^^^^^^^^^^^^^^^^^
  File "/home/airflow/.local/lib/python3.12/site-packages/selenium/webdriver/chrome/webdriver.py", line 73, in __init__
    self.service.start()
  File "/home/airflow/.local/lib/python3.12/site-packages/selenium/webdriver/common/service.py", line 98, in start
    self.assert_process_still_running()
  File "/home/airflow/.local/lib/python3.12/site-packages/selenium/webdriver/common/service.py", line 109, in assert_process_still_running
    raise WebDriverException(
selenium.common.exceptions.WebDriverException: Message: Service /opt/airflow/chromedriver unexpectedly exited. Status code was: 127
[2024-07-29T00:17:52.038+0000] {processor.py:842} WARNING - No viable dags retrieved from /opt/airflow/dags/airflow-dags/datalake/etl_products.py
[2024-07-29T00:17:52.058+0000] {processor.py:183} INFO - Processing /opt/airflow/dags/airflow-dags/datalake/etl_products.py took 1.098 seconds
[2024-07-29T00:18:22.243+0000] {processor.py:161} INFO - Started process (PID=4925) to work on /opt/airflow/dags/airflow-dags/datalake/etl_products.py
[2024-07-29T00:18:22.248+0000] {processor.py:830} INFO - Processing file /opt/airflow/dags/airflow-dags/datalake/etl_products.py for tasks to queue
[2024-07-29T00:18:22.249+0000] {logging_mixin.py:188} INFO - [2024-07-29T00:18:22.249+0000] {dagbag.py:540} INFO - Filling up the DagBag from /opt/airflow/dags/airflow-dags/datalake/etl_products.py
[2024-07-29T00:18:23.285+0000] {logging_mixin.py:188} INFO - [2024-07-29T00:18:23.282+0000] {dagbag.py:350} ERROR - Failed to import: /opt/airflow/dags/airflow-dags/datalake/etl_products.py
Traceback (most recent call last):
  File "/home/airflow/.local/lib/python3.12/site-packages/airflow/models/dagbag.py", line 346, in parse
    loader.exec_module(new_module)
  File "<frozen importlib._bootstrap_external>", line 995, in exec_module
  File "<frozen importlib._bootstrap>", line 488, in _call_with_frames_removed
  File "/opt/airflow/dags/airflow-dags/datalake/etl_products.py", line 25, in <module>
    driver = webdriver.Chrome(executable_path=r'/opt/airflow/chromedriver', options=options)
             ^^^^^^^^^^^^^^^^^^^^^^^^^^^^^^^^^^^^^^^^^^^^^^^^^^^^^^^^^^^^^^^^^^^^^^^^^^^^^^^
  File "/home/airflow/.local/lib/python3.12/site-packages/selenium/webdriver/chrome/webdriver.py", line 73, in __init__
    self.service.start()
  File "/home/airflow/.local/lib/python3.12/site-packages/selenium/webdriver/common/service.py", line 98, in start
    self.assert_process_still_running()
  File "/home/airflow/.local/lib/python3.12/site-packages/selenium/webdriver/common/service.py", line 109, in assert_process_still_running
    raise WebDriverException(
selenium.common.exceptions.WebDriverException: Message: Service /opt/airflow/chromedriver unexpectedly exited. Status code was: 127
[2024-07-29T00:18:23.313+0000] {processor.py:842} WARNING - No viable dags retrieved from /opt/airflow/dags/airflow-dags/datalake/etl_products.py
[2024-07-29T00:18:23.329+0000] {processor.py:183} INFO - Processing /opt/airflow/dags/airflow-dags/datalake/etl_products.py took 1.092 seconds
[2024-07-29T00:18:53.519+0000] {processor.py:161} INFO - Started process (PID=4943) to work on /opt/airflow/dags/airflow-dags/datalake/etl_products.py
[2024-07-29T00:18:53.519+0000] {processor.py:830} INFO - Processing file /opt/airflow/dags/airflow-dags/datalake/etl_products.py for tasks to queue
[2024-07-29T00:18:53.520+0000] {logging_mixin.py:188} INFO - [2024-07-29T00:18:53.520+0000] {dagbag.py:540} INFO - Filling up the DagBag from /opt/airflow/dags/airflow-dags/datalake/etl_products.py
[2024-07-29T00:18:54.554+0000] {logging_mixin.py:188} INFO - [2024-07-29T00:18:54.551+0000] {dagbag.py:350} ERROR - Failed to import: /opt/airflow/dags/airflow-dags/datalake/etl_products.py
Traceback (most recent call last):
  File "/home/airflow/.local/lib/python3.12/site-packages/airflow/models/dagbag.py", line 346, in parse
    loader.exec_module(new_module)
  File "<frozen importlib._bootstrap_external>", line 995, in exec_module
  File "<frozen importlib._bootstrap>", line 488, in _call_with_frames_removed
  File "/opt/airflow/dags/airflow-dags/datalake/etl_products.py", line 25, in <module>
    driver = webdriver.Chrome(executable_path=r'/opt/airflow/chromedriver', options=options)
             ^^^^^^^^^^^^^^^^^^^^^^^^^^^^^^^^^^^^^^^^^^^^^^^^^^^^^^^^^^^^^^^^^^^^^^^^^^^^^^^
  File "/home/airflow/.local/lib/python3.12/site-packages/selenium/webdriver/chrome/webdriver.py", line 73, in __init__
    self.service.start()
  File "/home/airflow/.local/lib/python3.12/site-packages/selenium/webdriver/common/service.py", line 98, in start
    self.assert_process_still_running()
  File "/home/airflow/.local/lib/python3.12/site-packages/selenium/webdriver/common/service.py", line 109, in assert_process_still_running
    raise WebDriverException(
selenium.common.exceptions.WebDriverException: Message: Service /opt/airflow/chromedriver unexpectedly exited. Status code was: 127
[2024-07-29T00:18:54.584+0000] {processor.py:842} WARNING - No viable dags retrieved from /opt/airflow/dags/airflow-dags/datalake/etl_products.py
[2024-07-29T00:18:54.598+0000] {processor.py:183} INFO - Processing /opt/airflow/dags/airflow-dags/datalake/etl_products.py took 1.083 seconds
[2024-07-29T00:19:24.797+0000] {processor.py:161} INFO - Started process (PID=4961) to work on /opt/airflow/dags/airflow-dags/datalake/etl_products.py
[2024-07-29T00:19:24.802+0000] {processor.py:830} INFO - Processing file /opt/airflow/dags/airflow-dags/datalake/etl_products.py for tasks to queue
[2024-07-29T00:19:24.805+0000] {logging_mixin.py:188} INFO - [2024-07-29T00:19:24.804+0000] {dagbag.py:540} INFO - Filling up the DagBag from /opt/airflow/dags/airflow-dags/datalake/etl_products.py
[2024-07-29T00:19:25.847+0000] {logging_mixin.py:188} INFO - [2024-07-29T00:19:25.843+0000] {dagbag.py:350} ERROR - Failed to import: /opt/airflow/dags/airflow-dags/datalake/etl_products.py
Traceback (most recent call last):
  File "/home/airflow/.local/lib/python3.12/site-packages/airflow/models/dagbag.py", line 346, in parse
    loader.exec_module(new_module)
  File "<frozen importlib._bootstrap_external>", line 995, in exec_module
  File "<frozen importlib._bootstrap>", line 488, in _call_with_frames_removed
  File "/opt/airflow/dags/airflow-dags/datalake/etl_products.py", line 25, in <module>
    driver = webdriver.Chrome(executable_path=r'/opt/airflow/chromedriver', options=options)
             ^^^^^^^^^^^^^^^^^^^^^^^^^^^^^^^^^^^^^^^^^^^^^^^^^^^^^^^^^^^^^^^^^^^^^^^^^^^^^^^
  File "/home/airflow/.local/lib/python3.12/site-packages/selenium/webdriver/chrome/webdriver.py", line 73, in __init__
    self.service.start()
  File "/home/airflow/.local/lib/python3.12/site-packages/selenium/webdriver/common/service.py", line 98, in start
    self.assert_process_still_running()
  File "/home/airflow/.local/lib/python3.12/site-packages/selenium/webdriver/common/service.py", line 109, in assert_process_still_running
    raise WebDriverException(
selenium.common.exceptions.WebDriverException: Message: Service /opt/airflow/chromedriver unexpectedly exited. Status code was: 127
[2024-07-29T00:19:25.877+0000] {processor.py:842} WARNING - No viable dags retrieved from /opt/airflow/dags/airflow-dags/datalake/etl_products.py
[2024-07-29T00:19:25.895+0000] {processor.py:183} INFO - Processing /opt/airflow/dags/airflow-dags/datalake/etl_products.py took 1.103 seconds
[2024-07-29T00:19:56.081+0000] {processor.py:161} INFO - Started process (PID=4979) to work on /opt/airflow/dags/airflow-dags/datalake/etl_products.py
[2024-07-29T00:19:56.086+0000] {processor.py:830} INFO - Processing file /opt/airflow/dags/airflow-dags/datalake/etl_products.py for tasks to queue
[2024-07-29T00:19:56.087+0000] {logging_mixin.py:188} INFO - [2024-07-29T00:19:56.087+0000] {dagbag.py:540} INFO - Filling up the DagBag from /opt/airflow/dags/airflow-dags/datalake/etl_products.py
[2024-07-29T00:19:57.119+0000] {logging_mixin.py:188} INFO - [2024-07-29T00:19:57.118+0000] {dagbag.py:350} ERROR - Failed to import: /opt/airflow/dags/airflow-dags/datalake/etl_products.py
Traceback (most recent call last):
  File "/home/airflow/.local/lib/python3.12/site-packages/airflow/models/dagbag.py", line 346, in parse
    loader.exec_module(new_module)
  File "<frozen importlib._bootstrap_external>", line 995, in exec_module
  File "<frozen importlib._bootstrap>", line 488, in _call_with_frames_removed
  File "/opt/airflow/dags/airflow-dags/datalake/etl_products.py", line 25, in <module>
    driver = webdriver.Chrome(executable_path=r'/opt/airflow/chromedriver', options=options)
             ^^^^^^^^^^^^^^^^^^^^^^^^^^^^^^^^^^^^^^^^^^^^^^^^^^^^^^^^^^^^^^^^^^^^^^^^^^^^^^^
  File "/home/airflow/.local/lib/python3.12/site-packages/selenium/webdriver/chrome/webdriver.py", line 73, in __init__
    self.service.start()
  File "/home/airflow/.local/lib/python3.12/site-packages/selenium/webdriver/common/service.py", line 98, in start
    self.assert_process_still_running()
  File "/home/airflow/.local/lib/python3.12/site-packages/selenium/webdriver/common/service.py", line 109, in assert_process_still_running
    raise WebDriverException(
selenium.common.exceptions.WebDriverException: Message: Service /opt/airflow/chromedriver unexpectedly exited. Status code was: 127
[2024-07-29T00:19:57.146+0000] {processor.py:842} WARNING - No viable dags retrieved from /opt/airflow/dags/airflow-dags/datalake/etl_products.py
[2024-07-29T00:19:57.162+0000] {processor.py:183} INFO - Processing /opt/airflow/dags/airflow-dags/datalake/etl_products.py took 1.087 seconds
[2024-07-29T00:20:27.312+0000] {processor.py:161} INFO - Started process (PID=4997) to work on /opt/airflow/dags/airflow-dags/datalake/etl_products.py
[2024-07-29T00:20:27.312+0000] {processor.py:830} INFO - Processing file /opt/airflow/dags/airflow-dags/datalake/etl_products.py for tasks to queue
[2024-07-29T00:20:27.314+0000] {logging_mixin.py:188} INFO - [2024-07-29T00:20:27.313+0000] {dagbag.py:540} INFO - Filling up the DagBag from /opt/airflow/dags/airflow-dags/datalake/etl_products.py
[2024-07-29T00:20:28.347+0000] {logging_mixin.py:188} INFO - [2024-07-29T00:20:28.344+0000] {dagbag.py:350} ERROR - Failed to import: /opt/airflow/dags/airflow-dags/datalake/etl_products.py
Traceback (most recent call last):
  File "/home/airflow/.local/lib/python3.12/site-packages/airflow/models/dagbag.py", line 346, in parse
    loader.exec_module(new_module)
  File "<frozen importlib._bootstrap_external>", line 995, in exec_module
  File "<frozen importlib._bootstrap>", line 488, in _call_with_frames_removed
  File "/opt/airflow/dags/airflow-dags/datalake/etl_products.py", line 25, in <module>
    driver = webdriver.Chrome(executable_path=r'/opt/airflow/chromedriver', options=options)
             ^^^^^^^^^^^^^^^^^^^^^^^^^^^^^^^^^^^^^^^^^^^^^^^^^^^^^^^^^^^^^^^^^^^^^^^^^^^^^^^
  File "/home/airflow/.local/lib/python3.12/site-packages/selenium/webdriver/chrome/webdriver.py", line 73, in __init__
    self.service.start()
  File "/home/airflow/.local/lib/python3.12/site-packages/selenium/webdriver/common/service.py", line 98, in start
    self.assert_process_still_running()
  File "/home/airflow/.local/lib/python3.12/site-packages/selenium/webdriver/common/service.py", line 109, in assert_process_still_running
    raise WebDriverException(
selenium.common.exceptions.WebDriverException: Message: Service /opt/airflow/chromedriver unexpectedly exited. Status code was: 127
[2024-07-29T00:20:28.379+0000] {processor.py:842} WARNING - No viable dags retrieved from /opt/airflow/dags/airflow-dags/datalake/etl_products.py
[2024-07-29T00:20:28.392+0000] {processor.py:183} INFO - Processing /opt/airflow/dags/airflow-dags/datalake/etl_products.py took 1.084 seconds
[2024-07-29T00:20:58.579+0000] {processor.py:161} INFO - Started process (PID=5015) to work on /opt/airflow/dags/airflow-dags/datalake/etl_products.py
[2024-07-29T00:20:58.580+0000] {processor.py:830} INFO - Processing file /opt/airflow/dags/airflow-dags/datalake/etl_products.py for tasks to queue
[2024-07-29T00:20:58.582+0000] {logging_mixin.py:188} INFO - [2024-07-29T00:20:58.582+0000] {dagbag.py:540} INFO - Filling up the DagBag from /opt/airflow/dags/airflow-dags/datalake/etl_products.py
[2024-07-29T00:20:59.618+0000] {logging_mixin.py:188} INFO - [2024-07-29T00:20:59.615+0000] {dagbag.py:350} ERROR - Failed to import: /opt/airflow/dags/airflow-dags/datalake/etl_products.py
Traceback (most recent call last):
  File "/home/airflow/.local/lib/python3.12/site-packages/airflow/models/dagbag.py", line 346, in parse
    loader.exec_module(new_module)
  File "<frozen importlib._bootstrap_external>", line 995, in exec_module
  File "<frozen importlib._bootstrap>", line 488, in _call_with_frames_removed
  File "/opt/airflow/dags/airflow-dags/datalake/etl_products.py", line 25, in <module>
    driver = webdriver.Chrome(executable_path=r'/opt/airflow/chromedriver', options=options)
             ^^^^^^^^^^^^^^^^^^^^^^^^^^^^^^^^^^^^^^^^^^^^^^^^^^^^^^^^^^^^^^^^^^^^^^^^^^^^^^^
  File "/home/airflow/.local/lib/python3.12/site-packages/selenium/webdriver/chrome/webdriver.py", line 73, in __init__
    self.service.start()
  File "/home/airflow/.local/lib/python3.12/site-packages/selenium/webdriver/common/service.py", line 98, in start
    self.assert_process_still_running()
  File "/home/airflow/.local/lib/python3.12/site-packages/selenium/webdriver/common/service.py", line 109, in assert_process_still_running
    raise WebDriverException(
selenium.common.exceptions.WebDriverException: Message: Service /opt/airflow/chromedriver unexpectedly exited. Status code was: 127
[2024-07-29T00:20:59.648+0000] {processor.py:842} WARNING - No viable dags retrieved from /opt/airflow/dags/airflow-dags/datalake/etl_products.py
[2024-07-29T00:20:59.662+0000] {processor.py:183} INFO - Processing /opt/airflow/dags/airflow-dags/datalake/etl_products.py took 1.089 seconds
[2024-07-29T00:21:29.866+0000] {processor.py:161} INFO - Started process (PID=5039) to work on /opt/airflow/dags/airflow-dags/datalake/etl_products.py
[2024-07-29T00:21:29.870+0000] {processor.py:830} INFO - Processing file /opt/airflow/dags/airflow-dags/datalake/etl_products.py for tasks to queue
[2024-07-29T00:21:29.872+0000] {logging_mixin.py:188} INFO - [2024-07-29T00:21:29.872+0000] {dagbag.py:540} INFO - Filling up the DagBag from /opt/airflow/dags/airflow-dags/datalake/etl_products.py
[2024-07-29T00:21:30.906+0000] {logging_mixin.py:188} INFO - [2024-07-29T00:21:30.902+0000] {dagbag.py:350} ERROR - Failed to import: /opt/airflow/dags/airflow-dags/datalake/etl_products.py
Traceback (most recent call last):
  File "/home/airflow/.local/lib/python3.12/site-packages/airflow/models/dagbag.py", line 346, in parse
    loader.exec_module(new_module)
  File "<frozen importlib._bootstrap_external>", line 995, in exec_module
  File "<frozen importlib._bootstrap>", line 488, in _call_with_frames_removed
  File "/opt/airflow/dags/airflow-dags/datalake/etl_products.py", line 25, in <module>
    driver = webdriver.Chrome(executable_path=r'/opt/airflow/chromedriver', options=options)
             ^^^^^^^^^^^^^^^^^^^^^^^^^^^^^^^^^^^^^^^^^^^^^^^^^^^^^^^^^^^^^^^^^^^^^^^^^^^^^^^
  File "/home/airflow/.local/lib/python3.12/site-packages/selenium/webdriver/chrome/webdriver.py", line 73, in __init__
    self.service.start()
  File "/home/airflow/.local/lib/python3.12/site-packages/selenium/webdriver/common/service.py", line 98, in start
    self.assert_process_still_running()
  File "/home/airflow/.local/lib/python3.12/site-packages/selenium/webdriver/common/service.py", line 109, in assert_process_still_running
    raise WebDriverException(
selenium.common.exceptions.WebDriverException: Message: Service /opt/airflow/chromedriver unexpectedly exited. Status code was: 127
[2024-07-29T00:21:30.930+0000] {processor.py:842} WARNING - No viable dags retrieved from /opt/airflow/dags/airflow-dags/datalake/etl_products.py
[2024-07-29T00:21:30.951+0000] {processor.py:183} INFO - Processing /opt/airflow/dags/airflow-dags/datalake/etl_products.py took 1.091 seconds
[2024-07-29T00:22:01.159+0000] {processor.py:161} INFO - Started process (PID=5057) to work on /opt/airflow/dags/airflow-dags/datalake/etl_products.py
[2024-07-29T00:22:01.163+0000] {processor.py:830} INFO - Processing file /opt/airflow/dags/airflow-dags/datalake/etl_products.py for tasks to queue
[2024-07-29T00:22:01.165+0000] {logging_mixin.py:188} INFO - [2024-07-29T00:22:01.165+0000] {dagbag.py:540} INFO - Filling up the DagBag from /opt/airflow/dags/airflow-dags/datalake/etl_products.py
[2024-07-29T00:22:02.205+0000] {logging_mixin.py:188} INFO - [2024-07-29T00:22:02.204+0000] {dagbag.py:350} ERROR - Failed to import: /opt/airflow/dags/airflow-dags/datalake/etl_products.py
Traceback (most recent call last):
  File "/home/airflow/.local/lib/python3.12/site-packages/airflow/models/dagbag.py", line 346, in parse
    loader.exec_module(new_module)
  File "<frozen importlib._bootstrap_external>", line 995, in exec_module
  File "<frozen importlib._bootstrap>", line 488, in _call_with_frames_removed
  File "/opt/airflow/dags/airflow-dags/datalake/etl_products.py", line 25, in <module>
    driver = webdriver.Chrome(executable_path=r'/opt/airflow/chromedriver', options=options)
             ^^^^^^^^^^^^^^^^^^^^^^^^^^^^^^^^^^^^^^^^^^^^^^^^^^^^^^^^^^^^^^^^^^^^^^^^^^^^^^^
  File "/home/airflow/.local/lib/python3.12/site-packages/selenium/webdriver/chrome/webdriver.py", line 73, in __init__
    self.service.start()
  File "/home/airflow/.local/lib/python3.12/site-packages/selenium/webdriver/common/service.py", line 98, in start
    self.assert_process_still_running()
  File "/home/airflow/.local/lib/python3.12/site-packages/selenium/webdriver/common/service.py", line 109, in assert_process_still_running
    raise WebDriverException(
selenium.common.exceptions.WebDriverException: Message: Service /opt/airflow/chromedriver unexpectedly exited. Status code was: 127
[2024-07-29T00:22:02.229+0000] {processor.py:842} WARNING - No viable dags retrieved from /opt/airflow/dags/airflow-dags/datalake/etl_products.py
[2024-07-29T00:22:02.249+0000] {processor.py:183} INFO - Processing /opt/airflow/dags/airflow-dags/datalake/etl_products.py took 1.096 seconds
[2024-07-29T00:22:32.403+0000] {processor.py:161} INFO - Started process (PID=5075) to work on /opt/airflow/dags/airflow-dags/datalake/etl_products.py
[2024-07-29T00:22:32.405+0000] {processor.py:830} INFO - Processing file /opt/airflow/dags/airflow-dags/datalake/etl_products.py for tasks to queue
[2024-07-29T00:22:32.406+0000] {logging_mixin.py:188} INFO - [2024-07-29T00:22:32.406+0000] {dagbag.py:540} INFO - Filling up the DagBag from /opt/airflow/dags/airflow-dags/datalake/etl_products.py
[2024-07-29T00:22:33.440+0000] {logging_mixin.py:188} INFO - [2024-07-29T00:22:33.436+0000] {dagbag.py:350} ERROR - Failed to import: /opt/airflow/dags/airflow-dags/datalake/etl_products.py
Traceback (most recent call last):
  File "/home/airflow/.local/lib/python3.12/site-packages/airflow/models/dagbag.py", line 346, in parse
    loader.exec_module(new_module)
  File "<frozen importlib._bootstrap_external>", line 995, in exec_module
  File "<frozen importlib._bootstrap>", line 488, in _call_with_frames_removed
  File "/opt/airflow/dags/airflow-dags/datalake/etl_products.py", line 25, in <module>
    driver = webdriver.Chrome(executable_path=r'/opt/airflow/chromedriver', options=options)
             ^^^^^^^^^^^^^^^^^^^^^^^^^^^^^^^^^^^^^^^^^^^^^^^^^^^^^^^^^^^^^^^^^^^^^^^^^^^^^^^
  File "/home/airflow/.local/lib/python3.12/site-packages/selenium/webdriver/chrome/webdriver.py", line 73, in __init__
    self.service.start()
  File "/home/airflow/.local/lib/python3.12/site-packages/selenium/webdriver/common/service.py", line 98, in start
    self.assert_process_still_running()
  File "/home/airflow/.local/lib/python3.12/site-packages/selenium/webdriver/common/service.py", line 109, in assert_process_still_running
    raise WebDriverException(
selenium.common.exceptions.WebDriverException: Message: Service /opt/airflow/chromedriver unexpectedly exited. Status code was: 127
[2024-07-29T00:22:33.471+0000] {processor.py:842} WARNING - No viable dags retrieved from /opt/airflow/dags/airflow-dags/datalake/etl_products.py
[2024-07-29T00:22:33.490+0000] {processor.py:183} INFO - Processing /opt/airflow/dags/airflow-dags/datalake/etl_products.py took 1.093 seconds
[2024-07-29T00:23:03.690+0000] {processor.py:161} INFO - Started process (PID=5093) to work on /opt/airflow/dags/airflow-dags/datalake/etl_products.py
[2024-07-29T00:23:03.694+0000] {processor.py:830} INFO - Processing file /opt/airflow/dags/airflow-dags/datalake/etl_products.py for tasks to queue
[2024-07-29T00:23:03.696+0000] {logging_mixin.py:188} INFO - [2024-07-29T00:23:03.695+0000] {dagbag.py:540} INFO - Filling up the DagBag from /opt/airflow/dags/airflow-dags/datalake/etl_products.py
[2024-07-29T00:23:04.729+0000] {logging_mixin.py:188} INFO - [2024-07-29T00:23:04.726+0000] {dagbag.py:350} ERROR - Failed to import: /opt/airflow/dags/airflow-dags/datalake/etl_products.py
Traceback (most recent call last):
  File "/home/airflow/.local/lib/python3.12/site-packages/airflow/models/dagbag.py", line 346, in parse
    loader.exec_module(new_module)
  File "<frozen importlib._bootstrap_external>", line 995, in exec_module
  File "<frozen importlib._bootstrap>", line 488, in _call_with_frames_removed
  File "/opt/airflow/dags/airflow-dags/datalake/etl_products.py", line 25, in <module>
    driver = webdriver.Chrome(executable_path=r'/opt/airflow/chromedriver', options=options)
             ^^^^^^^^^^^^^^^^^^^^^^^^^^^^^^^^^^^^^^^^^^^^^^^^^^^^^^^^^^^^^^^^^^^^^^^^^^^^^^^
  File "/home/airflow/.local/lib/python3.12/site-packages/selenium/webdriver/chrome/webdriver.py", line 73, in __init__
    self.service.start()
  File "/home/airflow/.local/lib/python3.12/site-packages/selenium/webdriver/common/service.py", line 98, in start
    self.assert_process_still_running()
  File "/home/airflow/.local/lib/python3.12/site-packages/selenium/webdriver/common/service.py", line 109, in assert_process_still_running
    raise WebDriverException(
selenium.common.exceptions.WebDriverException: Message: Service /opt/airflow/chromedriver unexpectedly exited. Status code was: 127
[2024-07-29T00:23:04.759+0000] {processor.py:842} WARNING - No viable dags retrieved from /opt/airflow/dags/airflow-dags/datalake/etl_products.py
[2024-07-29T00:23:04.777+0000] {processor.py:183} INFO - Processing /opt/airflow/dags/airflow-dags/datalake/etl_products.py took 1.092 seconds
[2024-07-29T00:23:34.971+0000] {processor.py:161} INFO - Started process (PID=5111) to work on /opt/airflow/dags/airflow-dags/datalake/etl_products.py
[2024-07-29T00:23:34.976+0000] {processor.py:830} INFO - Processing file /opt/airflow/dags/airflow-dags/datalake/etl_products.py for tasks to queue
[2024-07-29T00:23:34.977+0000] {logging_mixin.py:188} INFO - [2024-07-29T00:23:34.977+0000] {dagbag.py:540} INFO - Filling up the DagBag from /opt/airflow/dags/airflow-dags/datalake/etl_products.py
[2024-07-29T00:23:36.012+0000] {logging_mixin.py:188} INFO - [2024-07-29T00:23:36.008+0000] {dagbag.py:350} ERROR - Failed to import: /opt/airflow/dags/airflow-dags/datalake/etl_products.py
Traceback (most recent call last):
  File "/home/airflow/.local/lib/python3.12/site-packages/airflow/models/dagbag.py", line 346, in parse
    loader.exec_module(new_module)
  File "<frozen importlib._bootstrap_external>", line 995, in exec_module
  File "<frozen importlib._bootstrap>", line 488, in _call_with_frames_removed
  File "/opt/airflow/dags/airflow-dags/datalake/etl_products.py", line 25, in <module>
    driver = webdriver.Chrome(executable_path=r'/opt/airflow/chromedriver', options=options)
             ^^^^^^^^^^^^^^^^^^^^^^^^^^^^^^^^^^^^^^^^^^^^^^^^^^^^^^^^^^^^^^^^^^^^^^^^^^^^^^^
  File "/home/airflow/.local/lib/python3.12/site-packages/selenium/webdriver/chrome/webdriver.py", line 73, in __init__
    self.service.start()
  File "/home/airflow/.local/lib/python3.12/site-packages/selenium/webdriver/common/service.py", line 98, in start
    self.assert_process_still_running()
  File "/home/airflow/.local/lib/python3.12/site-packages/selenium/webdriver/common/service.py", line 109, in assert_process_still_running
    raise WebDriverException(
selenium.common.exceptions.WebDriverException: Message: Service /opt/airflow/chromedriver unexpectedly exited. Status code was: 127
[2024-07-29T00:23:36.041+0000] {processor.py:842} WARNING - No viable dags retrieved from /opt/airflow/dags/airflow-dags/datalake/etl_products.py
[2024-07-29T00:23:36.060+0000] {processor.py:183} INFO - Processing /opt/airflow/dags/airflow-dags/datalake/etl_products.py took 1.093 seconds
[2024-07-29T00:24:06.294+0000] {processor.py:161} INFO - Started process (PID=5129) to work on /opt/airflow/dags/airflow-dags/datalake/etl_products.py
[2024-07-29T00:24:06.299+0000] {processor.py:830} INFO - Processing file /opt/airflow/dags/airflow-dags/datalake/etl_products.py for tasks to queue
[2024-07-29T00:24:06.300+0000] {logging_mixin.py:188} INFO - [2024-07-29T00:24:06.300+0000] {dagbag.py:540} INFO - Filling up the DagBag from /opt/airflow/dags/airflow-dags/datalake/etl_products.py
[2024-07-29T00:24:07.334+0000] {logging_mixin.py:188} INFO - [2024-07-29T00:24:07.330+0000] {dagbag.py:350} ERROR - Failed to import: /opt/airflow/dags/airflow-dags/datalake/etl_products.py
Traceback (most recent call last):
  File "/home/airflow/.local/lib/python3.12/site-packages/airflow/models/dagbag.py", line 346, in parse
    loader.exec_module(new_module)
  File "<frozen importlib._bootstrap_external>", line 995, in exec_module
  File "<frozen importlib._bootstrap>", line 488, in _call_with_frames_removed
  File "/opt/airflow/dags/airflow-dags/datalake/etl_products.py", line 25, in <module>
    driver = webdriver.Chrome(executable_path=r'/opt/airflow/chromedriver', options=options)
             ^^^^^^^^^^^^^^^^^^^^^^^^^^^^^^^^^^^^^^^^^^^^^^^^^^^^^^^^^^^^^^^^^^^^^^^^^^^^^^^
  File "/home/airflow/.local/lib/python3.12/site-packages/selenium/webdriver/chrome/webdriver.py", line 73, in __init__
    self.service.start()
  File "/home/airflow/.local/lib/python3.12/site-packages/selenium/webdriver/common/service.py", line 98, in start
    self.assert_process_still_running()
  File "/home/airflow/.local/lib/python3.12/site-packages/selenium/webdriver/common/service.py", line 109, in assert_process_still_running
    raise WebDriverException(
selenium.common.exceptions.WebDriverException: Message: Service /opt/airflow/chromedriver unexpectedly exited. Status code was: 127
[2024-07-29T00:24:07.365+0000] {processor.py:842} WARNING - No viable dags retrieved from /opt/airflow/dags/airflow-dags/datalake/etl_products.py
[2024-07-29T00:24:07.384+0000] {processor.py:183} INFO - Processing /opt/airflow/dags/airflow-dags/datalake/etl_products.py took 1.095 seconds
[2024-07-29T00:24:37.554+0000] {processor.py:161} INFO - Started process (PID=5147) to work on /opt/airflow/dags/airflow-dags/datalake/etl_products.py
[2024-07-29T00:24:37.555+0000] {processor.py:830} INFO - Processing file /opt/airflow/dags/airflow-dags/datalake/etl_products.py for tasks to queue
[2024-07-29T00:24:37.556+0000] {logging_mixin.py:188} INFO - [2024-07-29T00:24:37.555+0000] {dagbag.py:540} INFO - Filling up the DagBag from /opt/airflow/dags/airflow-dags/datalake/etl_products.py
[2024-07-29T00:24:38.589+0000] {logging_mixin.py:188} INFO - [2024-07-29T00:24:38.586+0000] {dagbag.py:350} ERROR - Failed to import: /opt/airflow/dags/airflow-dags/datalake/etl_products.py
Traceback (most recent call last):
  File "/home/airflow/.local/lib/python3.12/site-packages/airflow/models/dagbag.py", line 346, in parse
    loader.exec_module(new_module)
  File "<frozen importlib._bootstrap_external>", line 995, in exec_module
  File "<frozen importlib._bootstrap>", line 488, in _call_with_frames_removed
  File "/opt/airflow/dags/airflow-dags/datalake/etl_products.py", line 25, in <module>
    driver = webdriver.Chrome(executable_path=r'/opt/airflow/chromedriver', options=options)
             ^^^^^^^^^^^^^^^^^^^^^^^^^^^^^^^^^^^^^^^^^^^^^^^^^^^^^^^^^^^^^^^^^^^^^^^^^^^^^^^
  File "/home/airflow/.local/lib/python3.12/site-packages/selenium/webdriver/chrome/webdriver.py", line 73, in __init__
    self.service.start()
  File "/home/airflow/.local/lib/python3.12/site-packages/selenium/webdriver/common/service.py", line 98, in start
    self.assert_process_still_running()
  File "/home/airflow/.local/lib/python3.12/site-packages/selenium/webdriver/common/service.py", line 109, in assert_process_still_running
    raise WebDriverException(
selenium.common.exceptions.WebDriverException: Message: Service /opt/airflow/chromedriver unexpectedly exited. Status code was: 127
[2024-07-29T00:24:38.619+0000] {processor.py:842} WARNING - No viable dags retrieved from /opt/airflow/dags/airflow-dags/datalake/etl_products.py
[2024-07-29T00:24:38.641+0000] {processor.py:183} INFO - Processing /opt/airflow/dags/airflow-dags/datalake/etl_products.py took 1.093 seconds
[2024-07-29T00:25:08.860+0000] {processor.py:161} INFO - Started process (PID=5165) to work on /opt/airflow/dags/airflow-dags/datalake/etl_products.py
[2024-07-29T00:25:08.865+0000] {processor.py:830} INFO - Processing file /opt/airflow/dags/airflow-dags/datalake/etl_products.py for tasks to queue
[2024-07-29T00:25:08.866+0000] {logging_mixin.py:188} INFO - [2024-07-29T00:25:08.866+0000] {dagbag.py:540} INFO - Filling up the DagBag from /opt/airflow/dags/airflow-dags/datalake/etl_products.py
[2024-07-29T00:25:09.901+0000] {logging_mixin.py:188} INFO - [2024-07-29T00:25:09.898+0000] {dagbag.py:350} ERROR - Failed to import: /opt/airflow/dags/airflow-dags/datalake/etl_products.py
Traceback (most recent call last):
  File "/home/airflow/.local/lib/python3.12/site-packages/airflow/models/dagbag.py", line 346, in parse
    loader.exec_module(new_module)
  File "<frozen importlib._bootstrap_external>", line 995, in exec_module
  File "<frozen importlib._bootstrap>", line 488, in _call_with_frames_removed
  File "/opt/airflow/dags/airflow-dags/datalake/etl_products.py", line 25, in <module>
    driver = webdriver.Chrome(executable_path=r'/opt/airflow/chromedriver', options=options)
             ^^^^^^^^^^^^^^^^^^^^^^^^^^^^^^^^^^^^^^^^^^^^^^^^^^^^^^^^^^^^^^^^^^^^^^^^^^^^^^^
  File "/home/airflow/.local/lib/python3.12/site-packages/selenium/webdriver/chrome/webdriver.py", line 73, in __init__
    self.service.start()
  File "/home/airflow/.local/lib/python3.12/site-packages/selenium/webdriver/common/service.py", line 98, in start
    self.assert_process_still_running()
  File "/home/airflow/.local/lib/python3.12/site-packages/selenium/webdriver/common/service.py", line 109, in assert_process_still_running
    raise WebDriverException(
selenium.common.exceptions.WebDriverException: Message: Service /opt/airflow/chromedriver unexpectedly exited. Status code was: 127
[2024-07-29T00:25:09.934+0000] {processor.py:842} WARNING - No viable dags retrieved from /opt/airflow/dags/airflow-dags/datalake/etl_products.py
[2024-07-29T00:25:09.953+0000] {processor.py:183} INFO - Processing /opt/airflow/dags/airflow-dags/datalake/etl_products.py took 1.101 seconds
[2024-07-29T00:25:40.135+0000] {processor.py:161} INFO - Started process (PID=5183) to work on /opt/airflow/dags/airflow-dags/datalake/etl_products.py
[2024-07-29T00:25:40.140+0000] {processor.py:830} INFO - Processing file /opt/airflow/dags/airflow-dags/datalake/etl_products.py for tasks to queue
[2024-07-29T00:25:40.141+0000] {logging_mixin.py:188} INFO - [2024-07-29T00:25:40.141+0000] {dagbag.py:540} INFO - Filling up the DagBag from /opt/airflow/dags/airflow-dags/datalake/etl_products.py
[2024-07-29T00:25:41.177+0000] {logging_mixin.py:188} INFO - [2024-07-29T00:25:41.173+0000] {dagbag.py:350} ERROR - Failed to import: /opt/airflow/dags/airflow-dags/datalake/etl_products.py
Traceback (most recent call last):
  File "/home/airflow/.local/lib/python3.12/site-packages/airflow/models/dagbag.py", line 346, in parse
    loader.exec_module(new_module)
  File "<frozen importlib._bootstrap_external>", line 995, in exec_module
  File "<frozen importlib._bootstrap>", line 488, in _call_with_frames_removed
  File "/opt/airflow/dags/airflow-dags/datalake/etl_products.py", line 25, in <module>
    driver = webdriver.Chrome(executable_path=r'/opt/airflow/chromedriver', options=options)
             ^^^^^^^^^^^^^^^^^^^^^^^^^^^^^^^^^^^^^^^^^^^^^^^^^^^^^^^^^^^^^^^^^^^^^^^^^^^^^^^
  File "/home/airflow/.local/lib/python3.12/site-packages/selenium/webdriver/chrome/webdriver.py", line 73, in __init__
    self.service.start()
  File "/home/airflow/.local/lib/python3.12/site-packages/selenium/webdriver/common/service.py", line 98, in start
    self.assert_process_still_running()
  File "/home/airflow/.local/lib/python3.12/site-packages/selenium/webdriver/common/service.py", line 109, in assert_process_still_running
    raise WebDriverException(
selenium.common.exceptions.WebDriverException: Message: Service /opt/airflow/chromedriver unexpectedly exited. Status code was: 127
[2024-07-29T00:25:41.207+0000] {processor.py:842} WARNING - No viable dags retrieved from /opt/airflow/dags/airflow-dags/datalake/etl_products.py
[2024-07-29T00:25:41.226+0000] {processor.py:183} INFO - Processing /opt/airflow/dags/airflow-dags/datalake/etl_products.py took 1.095 seconds
[2024-07-29T00:26:11.447+0000] {processor.py:161} INFO - Started process (PID=5201) to work on /opt/airflow/dags/airflow-dags/datalake/etl_products.py
[2024-07-29T00:26:11.449+0000] {processor.py:830} INFO - Processing file /opt/airflow/dags/airflow-dags/datalake/etl_products.py for tasks to queue
[2024-07-29T00:26:11.450+0000] {logging_mixin.py:188} INFO - [2024-07-29T00:26:11.450+0000] {dagbag.py:540} INFO - Filling up the DagBag from /opt/airflow/dags/airflow-dags/datalake/etl_products.py
[2024-07-29T00:26:12.486+0000] {logging_mixin.py:188} INFO - [2024-07-29T00:26:12.482+0000] {dagbag.py:350} ERROR - Failed to import: /opt/airflow/dags/airflow-dags/datalake/etl_products.py
Traceback (most recent call last):
  File "/home/airflow/.local/lib/python3.12/site-packages/airflow/models/dagbag.py", line 346, in parse
    loader.exec_module(new_module)
  File "<frozen importlib._bootstrap_external>", line 995, in exec_module
  File "<frozen importlib._bootstrap>", line 488, in _call_with_frames_removed
  File "/opt/airflow/dags/airflow-dags/datalake/etl_products.py", line 25, in <module>
    driver = webdriver.Chrome(executable_path=r'/opt/airflow/chromedriver', options=options)
             ^^^^^^^^^^^^^^^^^^^^^^^^^^^^^^^^^^^^^^^^^^^^^^^^^^^^^^^^^^^^^^^^^^^^^^^^^^^^^^^
  File "/home/airflow/.local/lib/python3.12/site-packages/selenium/webdriver/chrome/webdriver.py", line 73, in __init__
    self.service.start()
  File "/home/airflow/.local/lib/python3.12/site-packages/selenium/webdriver/common/service.py", line 98, in start
    self.assert_process_still_running()
  File "/home/airflow/.local/lib/python3.12/site-packages/selenium/webdriver/common/service.py", line 109, in assert_process_still_running
    raise WebDriverException(
selenium.common.exceptions.WebDriverException: Message: Service /opt/airflow/chromedriver unexpectedly exited. Status code was: 127
[2024-07-29T00:26:12.516+0000] {processor.py:842} WARNING - No viable dags retrieved from /opt/airflow/dags/airflow-dags/datalake/etl_products.py
[2024-07-29T00:26:12.535+0000] {processor.py:183} INFO - Processing /opt/airflow/dags/airflow-dags/datalake/etl_products.py took 1.095 seconds
[2024-07-29T00:26:42.705+0000] {processor.py:161} INFO - Started process (PID=5219) to work on /opt/airflow/dags/airflow-dags/datalake/etl_products.py
[2024-07-29T00:26:42.710+0000] {processor.py:830} INFO - Processing file /opt/airflow/dags/airflow-dags/datalake/etl_products.py for tasks to queue
[2024-07-29T00:26:42.712+0000] {logging_mixin.py:188} INFO - [2024-07-29T00:26:42.711+0000] {dagbag.py:540} INFO - Filling up the DagBag from /opt/airflow/dags/airflow-dags/datalake/etl_products.py
[2024-07-29T00:26:43.757+0000] {logging_mixin.py:188} INFO - [2024-07-29T00:26:43.756+0000] {dagbag.py:350} ERROR - Failed to import: /opt/airflow/dags/airflow-dags/datalake/etl_products.py
Traceback (most recent call last):
  File "/home/airflow/.local/lib/python3.12/site-packages/airflow/models/dagbag.py", line 346, in parse
    loader.exec_module(new_module)
  File "<frozen importlib._bootstrap_external>", line 995, in exec_module
  File "<frozen importlib._bootstrap>", line 488, in _call_with_frames_removed
  File "/opt/airflow/dags/airflow-dags/datalake/etl_products.py", line 25, in <module>
    driver = webdriver.Chrome(executable_path=r'/opt/airflow/chromedriver', options=options)
             ^^^^^^^^^^^^^^^^^^^^^^^^^^^^^^^^^^^^^^^^^^^^^^^^^^^^^^^^^^^^^^^^^^^^^^^^^^^^^^^
  File "/home/airflow/.local/lib/python3.12/site-packages/selenium/webdriver/chrome/webdriver.py", line 73, in __init__
    self.service.start()
  File "/home/airflow/.local/lib/python3.12/site-packages/selenium/webdriver/common/service.py", line 98, in start
    self.assert_process_still_running()
  File "/home/airflow/.local/lib/python3.12/site-packages/selenium/webdriver/common/service.py", line 109, in assert_process_still_running
    raise WebDriverException(
selenium.common.exceptions.WebDriverException: Message: Service /opt/airflow/chromedriver unexpectedly exited. Status code was: 127
[2024-07-29T00:26:43.785+0000] {processor.py:842} WARNING - No viable dags retrieved from /opt/airflow/dags/airflow-dags/datalake/etl_products.py
[2024-07-29T00:26:43.810+0000] {processor.py:183} INFO - Processing /opt/airflow/dags/airflow-dags/datalake/etl_products.py took 1.109 seconds
[2024-07-29T00:27:13.991+0000] {processor.py:161} INFO - Started process (PID=5237) to work on /opt/airflow/dags/airflow-dags/datalake/etl_products.py
[2024-07-29T00:27:13.995+0000] {processor.py:830} INFO - Processing file /opt/airflow/dags/airflow-dags/datalake/etl_products.py for tasks to queue
[2024-07-29T00:27:13.996+0000] {logging_mixin.py:188} INFO - [2024-07-29T00:27:13.996+0000] {dagbag.py:540} INFO - Filling up the DagBag from /opt/airflow/dags/airflow-dags/datalake/etl_products.py
[2024-07-29T00:27:15.034+0000] {logging_mixin.py:188} INFO - [2024-07-29T00:27:15.031+0000] {dagbag.py:350} ERROR - Failed to import: /opt/airflow/dags/airflow-dags/datalake/etl_products.py
Traceback (most recent call last):
  File "/home/airflow/.local/lib/python3.12/site-packages/airflow/models/dagbag.py", line 346, in parse
    loader.exec_module(new_module)
  File "<frozen importlib._bootstrap_external>", line 995, in exec_module
  File "<frozen importlib._bootstrap>", line 488, in _call_with_frames_removed
  File "/opt/airflow/dags/airflow-dags/datalake/etl_products.py", line 25, in <module>
    driver = webdriver.Chrome(executable_path=r'/opt/airflow/chromedriver', options=options)
             ^^^^^^^^^^^^^^^^^^^^^^^^^^^^^^^^^^^^^^^^^^^^^^^^^^^^^^^^^^^^^^^^^^^^^^^^^^^^^^^
  File "/home/airflow/.local/lib/python3.12/site-packages/selenium/webdriver/chrome/webdriver.py", line 73, in __init__
    self.service.start()
  File "/home/airflow/.local/lib/python3.12/site-packages/selenium/webdriver/common/service.py", line 98, in start
    self.assert_process_still_running()
  File "/home/airflow/.local/lib/python3.12/site-packages/selenium/webdriver/common/service.py", line 109, in assert_process_still_running
    raise WebDriverException(
selenium.common.exceptions.WebDriverException: Message: Service /opt/airflow/chromedriver unexpectedly exited. Status code was: 127
[2024-07-29T00:27:15.063+0000] {processor.py:842} WARNING - No viable dags retrieved from /opt/airflow/dags/airflow-dags/datalake/etl_products.py
[2024-07-29T00:27:15.083+0000] {processor.py:183} INFO - Processing /opt/airflow/dags/airflow-dags/datalake/etl_products.py took 1.096 seconds
[2024-07-29T00:27:45.290+0000] {processor.py:161} INFO - Started process (PID=5255) to work on /opt/airflow/dags/airflow-dags/datalake/etl_products.py
[2024-07-29T00:27:45.295+0000] {processor.py:830} INFO - Processing file /opt/airflow/dags/airflow-dags/datalake/etl_products.py for tasks to queue
[2024-07-29T00:27:45.296+0000] {logging_mixin.py:188} INFO - [2024-07-29T00:27:45.296+0000] {dagbag.py:540} INFO - Filling up the DagBag from /opt/airflow/dags/airflow-dags/datalake/etl_products.py
[2024-07-29T00:27:46.338+0000] {logging_mixin.py:188} INFO - [2024-07-29T00:27:46.335+0000] {dagbag.py:350} ERROR - Failed to import: /opt/airflow/dags/airflow-dags/datalake/etl_products.py
Traceback (most recent call last):
  File "/home/airflow/.local/lib/python3.12/site-packages/airflow/models/dagbag.py", line 346, in parse
    loader.exec_module(new_module)
  File "<frozen importlib._bootstrap_external>", line 995, in exec_module
  File "<frozen importlib._bootstrap>", line 488, in _call_with_frames_removed
  File "/opt/airflow/dags/airflow-dags/datalake/etl_products.py", line 25, in <module>
    driver = webdriver.Chrome(executable_path=r'/opt/airflow/chromedriver', options=options)
             ^^^^^^^^^^^^^^^^^^^^^^^^^^^^^^^^^^^^^^^^^^^^^^^^^^^^^^^^^^^^^^^^^^^^^^^^^^^^^^^
  File "/home/airflow/.local/lib/python3.12/site-packages/selenium/webdriver/chrome/webdriver.py", line 73, in __init__
    self.service.start()
  File "/home/airflow/.local/lib/python3.12/site-packages/selenium/webdriver/common/service.py", line 98, in start
    self.assert_process_still_running()
  File "/home/airflow/.local/lib/python3.12/site-packages/selenium/webdriver/common/service.py", line 109, in assert_process_still_running
    raise WebDriverException(
selenium.common.exceptions.WebDriverException: Message: Service /opt/airflow/chromedriver unexpectedly exited. Status code was: 127
[2024-07-29T00:27:46.369+0000] {processor.py:842} WARNING - No viable dags retrieved from /opt/airflow/dags/airflow-dags/datalake/etl_products.py
[2024-07-29T00:27:46.386+0000] {processor.py:183} INFO - Processing /opt/airflow/dags/airflow-dags/datalake/etl_products.py took 1.103 seconds
[2024-07-29T00:28:16.597+0000] {processor.py:161} INFO - Started process (PID=5273) to work on /opt/airflow/dags/airflow-dags/datalake/etl_products.py
[2024-07-29T00:28:16.598+0000] {processor.py:830} INFO - Processing file /opt/airflow/dags/airflow-dags/datalake/etl_products.py for tasks to queue
[2024-07-29T00:28:16.599+0000] {logging_mixin.py:188} INFO - [2024-07-29T00:28:16.599+0000] {dagbag.py:540} INFO - Filling up the DagBag from /opt/airflow/dags/airflow-dags/datalake/etl_products.py
[2024-07-29T00:28:17.634+0000] {logging_mixin.py:188} INFO - [2024-07-29T00:28:17.632+0000] {dagbag.py:350} ERROR - Failed to import: /opt/airflow/dags/airflow-dags/datalake/etl_products.py
Traceback (most recent call last):
  File "/home/airflow/.local/lib/python3.12/site-packages/airflow/models/dagbag.py", line 346, in parse
    loader.exec_module(new_module)
  File "<frozen importlib._bootstrap_external>", line 995, in exec_module
  File "<frozen importlib._bootstrap>", line 488, in _call_with_frames_removed
  File "/opt/airflow/dags/airflow-dags/datalake/etl_products.py", line 25, in <module>
    driver = webdriver.Chrome(executable_path=r'/opt/airflow/chromedriver', options=options)
             ^^^^^^^^^^^^^^^^^^^^^^^^^^^^^^^^^^^^^^^^^^^^^^^^^^^^^^^^^^^^^^^^^^^^^^^^^^^^^^^
  File "/home/airflow/.local/lib/python3.12/site-packages/selenium/webdriver/chrome/webdriver.py", line 73, in __init__
    self.service.start()
  File "/home/airflow/.local/lib/python3.12/site-packages/selenium/webdriver/common/service.py", line 98, in start
    self.assert_process_still_running()
  File "/home/airflow/.local/lib/python3.12/site-packages/selenium/webdriver/common/service.py", line 109, in assert_process_still_running
    raise WebDriverException(
selenium.common.exceptions.WebDriverException: Message: Service /opt/airflow/chromedriver unexpectedly exited. Status code was: 127
[2024-07-29T00:28:17.666+0000] {processor.py:842} WARNING - No viable dags retrieved from /opt/airflow/dags/airflow-dags/datalake/etl_products.py
[2024-07-29T00:28:17.685+0000] {processor.py:183} INFO - Processing /opt/airflow/dags/airflow-dags/datalake/etl_products.py took 1.092 seconds
[2024-07-29T00:28:47.872+0000] {processor.py:161} INFO - Started process (PID=5291) to work on /opt/airflow/dags/airflow-dags/datalake/etl_products.py
[2024-07-29T00:28:47.873+0000] {processor.py:830} INFO - Processing file /opt/airflow/dags/airflow-dags/datalake/etl_products.py for tasks to queue
[2024-07-29T00:28:47.874+0000] {logging_mixin.py:188} INFO - [2024-07-29T00:28:47.874+0000] {dagbag.py:540} INFO - Filling up the DagBag from /opt/airflow/dags/airflow-dags/datalake/etl_products.py
[2024-07-29T00:28:48.909+0000] {logging_mixin.py:188} INFO - [2024-07-29T00:28:48.908+0000] {dagbag.py:350} ERROR - Failed to import: /opt/airflow/dags/airflow-dags/datalake/etl_products.py
Traceback (most recent call last):
  File "/home/airflow/.local/lib/python3.12/site-packages/airflow/models/dagbag.py", line 346, in parse
    loader.exec_module(new_module)
  File "<frozen importlib._bootstrap_external>", line 995, in exec_module
  File "<frozen importlib._bootstrap>", line 488, in _call_with_frames_removed
  File "/opt/airflow/dags/airflow-dags/datalake/etl_products.py", line 25, in <module>
    driver = webdriver.Chrome(executable_path=r'/opt/airflow/chromedriver', options=options)
             ^^^^^^^^^^^^^^^^^^^^^^^^^^^^^^^^^^^^^^^^^^^^^^^^^^^^^^^^^^^^^^^^^^^^^^^^^^^^^^^
  File "/home/airflow/.local/lib/python3.12/site-packages/selenium/webdriver/chrome/webdriver.py", line 73, in __init__
    self.service.start()
  File "/home/airflow/.local/lib/python3.12/site-packages/selenium/webdriver/common/service.py", line 98, in start
    self.assert_process_still_running()
  File "/home/airflow/.local/lib/python3.12/site-packages/selenium/webdriver/common/service.py", line 109, in assert_process_still_running
    raise WebDriverException(
selenium.common.exceptions.WebDriverException: Message: Service /opt/airflow/chromedriver unexpectedly exited. Status code was: 127
[2024-07-29T00:28:48.939+0000] {processor.py:842} WARNING - No viable dags retrieved from /opt/airflow/dags/airflow-dags/datalake/etl_products.py
[2024-07-29T00:28:48.958+0000] {processor.py:183} INFO - Processing /opt/airflow/dags/airflow-dags/datalake/etl_products.py took 1.090 seconds
[2024-07-29T00:29:19.151+0000] {processor.py:161} INFO - Started process (PID=5309) to work on /opt/airflow/dags/airflow-dags/datalake/etl_products.py
[2024-07-29T00:29:19.152+0000] {processor.py:830} INFO - Processing file /opt/airflow/dags/airflow-dags/datalake/etl_products.py for tasks to queue
[2024-07-29T00:29:19.153+0000] {logging_mixin.py:188} INFO - [2024-07-29T00:29:19.153+0000] {dagbag.py:540} INFO - Filling up the DagBag from /opt/airflow/dags/airflow-dags/datalake/etl_products.py
[2024-07-29T00:29:20.187+0000] {logging_mixin.py:188} INFO - [2024-07-29T00:29:20.184+0000] {dagbag.py:350} ERROR - Failed to import: /opt/airflow/dags/airflow-dags/datalake/etl_products.py
Traceback (most recent call last):
  File "/home/airflow/.local/lib/python3.12/site-packages/airflow/models/dagbag.py", line 346, in parse
    loader.exec_module(new_module)
  File "<frozen importlib._bootstrap_external>", line 995, in exec_module
  File "<frozen importlib._bootstrap>", line 488, in _call_with_frames_removed
  File "/opt/airflow/dags/airflow-dags/datalake/etl_products.py", line 25, in <module>
    driver = webdriver.Chrome(executable_path=r'/opt/airflow/chromedriver', options=options)
             ^^^^^^^^^^^^^^^^^^^^^^^^^^^^^^^^^^^^^^^^^^^^^^^^^^^^^^^^^^^^^^^^^^^^^^^^^^^^^^^
  File "/home/airflow/.local/lib/python3.12/site-packages/selenium/webdriver/chrome/webdriver.py", line 73, in __init__
    self.service.start()
  File "/home/airflow/.local/lib/python3.12/site-packages/selenium/webdriver/common/service.py", line 98, in start
    self.assert_process_still_running()
  File "/home/airflow/.local/lib/python3.12/site-packages/selenium/webdriver/common/service.py", line 109, in assert_process_still_running
    raise WebDriverException(
selenium.common.exceptions.WebDriverException: Message: Service /opt/airflow/chromedriver unexpectedly exited. Status code was: 127
[2024-07-29T00:29:20.212+0000] {processor.py:842} WARNING - No viable dags retrieved from /opt/airflow/dags/airflow-dags/datalake/etl_products.py
[2024-07-29T00:29:20.226+0000] {processor.py:183} INFO - Processing /opt/airflow/dags/airflow-dags/datalake/etl_products.py took 1.079 seconds
[2024-07-29T00:29:50.440+0000] {processor.py:161} INFO - Started process (PID=5327) to work on /opt/airflow/dags/airflow-dags/datalake/etl_products.py
[2024-07-29T00:29:50.444+0000] {processor.py:830} INFO - Processing file /opt/airflow/dags/airflow-dags/datalake/etl_products.py for tasks to queue
[2024-07-29T00:29:50.445+0000] {logging_mixin.py:188} INFO - [2024-07-29T00:29:50.445+0000] {dagbag.py:540} INFO - Filling up the DagBag from /opt/airflow/dags/airflow-dags/datalake/etl_products.py
[2024-07-29T00:29:51.479+0000] {logging_mixin.py:188} INFO - [2024-07-29T00:29:51.476+0000] {dagbag.py:350} ERROR - Failed to import: /opt/airflow/dags/airflow-dags/datalake/etl_products.py
Traceback (most recent call last):
  File "/home/airflow/.local/lib/python3.12/site-packages/airflow/models/dagbag.py", line 346, in parse
    loader.exec_module(new_module)
  File "<frozen importlib._bootstrap_external>", line 995, in exec_module
  File "<frozen importlib._bootstrap>", line 488, in _call_with_frames_removed
  File "/opt/airflow/dags/airflow-dags/datalake/etl_products.py", line 25, in <module>
    driver = webdriver.Chrome(executable_path=r'/opt/airflow/chromedriver', options=options)
             ^^^^^^^^^^^^^^^^^^^^^^^^^^^^^^^^^^^^^^^^^^^^^^^^^^^^^^^^^^^^^^^^^^^^^^^^^^^^^^^
  File "/home/airflow/.local/lib/python3.12/site-packages/selenium/webdriver/chrome/webdriver.py", line 73, in __init__
    self.service.start()
  File "/home/airflow/.local/lib/python3.12/site-packages/selenium/webdriver/common/service.py", line 98, in start
    self.assert_process_still_running()
  File "/home/airflow/.local/lib/python3.12/site-packages/selenium/webdriver/common/service.py", line 109, in assert_process_still_running
    raise WebDriverException(
selenium.common.exceptions.WebDriverException: Message: Service /opt/airflow/chromedriver unexpectedly exited. Status code was: 127
[2024-07-29T00:29:51.504+0000] {processor.py:842} WARNING - No viable dags retrieved from /opt/airflow/dags/airflow-dags/datalake/etl_products.py
[2024-07-29T00:29:51.522+0000] {processor.py:183} INFO - Processing /opt/airflow/dags/airflow-dags/datalake/etl_products.py took 1.087 seconds
[2024-07-29T00:30:21.706+0000] {processor.py:161} INFO - Started process (PID=5345) to work on /opt/airflow/dags/airflow-dags/datalake/etl_products.py
[2024-07-29T00:30:21.711+0000] {processor.py:830} INFO - Processing file /opt/airflow/dags/airflow-dags/datalake/etl_products.py for tasks to queue
[2024-07-29T00:30:21.713+0000] {logging_mixin.py:188} INFO - [2024-07-29T00:30:21.712+0000] {dagbag.py:540} INFO - Filling up the DagBag from /opt/airflow/dags/airflow-dags/datalake/etl_products.py
[2024-07-29T00:30:22.749+0000] {logging_mixin.py:188} INFO - [2024-07-29T00:30:22.746+0000] {dagbag.py:350} ERROR - Failed to import: /opt/airflow/dags/airflow-dags/datalake/etl_products.py
Traceback (most recent call last):
  File "/home/airflow/.local/lib/python3.12/site-packages/airflow/models/dagbag.py", line 346, in parse
    loader.exec_module(new_module)
  File "<frozen importlib._bootstrap_external>", line 995, in exec_module
  File "<frozen importlib._bootstrap>", line 488, in _call_with_frames_removed
  File "/opt/airflow/dags/airflow-dags/datalake/etl_products.py", line 25, in <module>
    driver = webdriver.Chrome(executable_path=r'/opt/airflow/chromedriver', options=options)
             ^^^^^^^^^^^^^^^^^^^^^^^^^^^^^^^^^^^^^^^^^^^^^^^^^^^^^^^^^^^^^^^^^^^^^^^^^^^^^^^
  File "/home/airflow/.local/lib/python3.12/site-packages/selenium/webdriver/chrome/webdriver.py", line 73, in __init__
    self.service.start()
  File "/home/airflow/.local/lib/python3.12/site-packages/selenium/webdriver/common/service.py", line 98, in start
    self.assert_process_still_running()
  File "/home/airflow/.local/lib/python3.12/site-packages/selenium/webdriver/common/service.py", line 109, in assert_process_still_running
    raise WebDriverException(
selenium.common.exceptions.WebDriverException: Message: Service /opt/airflow/chromedriver unexpectedly exited. Status code was: 127
[2024-07-29T00:30:22.790+0000] {processor.py:842} WARNING - No viable dags retrieved from /opt/airflow/dags/airflow-dags/datalake/etl_products.py
[2024-07-29T00:30:22.804+0000] {processor.py:183} INFO - Processing /opt/airflow/dags/airflow-dags/datalake/etl_products.py took 1.104 seconds
[2024-07-29T00:30:53.003+0000] {processor.py:161} INFO - Started process (PID=5363) to work on /opt/airflow/dags/airflow-dags/datalake/etl_products.py
[2024-07-29T00:30:53.008+0000] {processor.py:830} INFO - Processing file /opt/airflow/dags/airflow-dags/datalake/etl_products.py for tasks to queue
[2024-07-29T00:30:53.009+0000] {logging_mixin.py:188} INFO - [2024-07-29T00:30:53.009+0000] {dagbag.py:540} INFO - Filling up the DagBag from /opt/airflow/dags/airflow-dags/datalake/etl_products.py
[2024-07-29T00:30:54.053+0000] {logging_mixin.py:188} INFO - [2024-07-29T00:30:54.050+0000] {dagbag.py:350} ERROR - Failed to import: /opt/airflow/dags/airflow-dags/datalake/etl_products.py
Traceback (most recent call last):
  File "/home/airflow/.local/lib/python3.12/site-packages/airflow/models/dagbag.py", line 346, in parse
    loader.exec_module(new_module)
  File "<frozen importlib._bootstrap_external>", line 995, in exec_module
  File "<frozen importlib._bootstrap>", line 488, in _call_with_frames_removed
  File "/opt/airflow/dags/airflow-dags/datalake/etl_products.py", line 25, in <module>
    driver = webdriver.Chrome(executable_path=r'/opt/airflow/chromedriver', options=options)
             ^^^^^^^^^^^^^^^^^^^^^^^^^^^^^^^^^^^^^^^^^^^^^^^^^^^^^^^^^^^^^^^^^^^^^^^^^^^^^^^
  File "/home/airflow/.local/lib/python3.12/site-packages/selenium/webdriver/chrome/webdriver.py", line 73, in __init__
    self.service.start()
  File "/home/airflow/.local/lib/python3.12/site-packages/selenium/webdriver/common/service.py", line 98, in start
    self.assert_process_still_running()
  File "/home/airflow/.local/lib/python3.12/site-packages/selenium/webdriver/common/service.py", line 109, in assert_process_still_running
    raise WebDriverException(
selenium.common.exceptions.WebDriverException: Message: Service /opt/airflow/chromedriver unexpectedly exited. Status code was: 127
[2024-07-29T00:30:54.082+0000] {processor.py:842} WARNING - No viable dags retrieved from /opt/airflow/dags/airflow-dags/datalake/etl_products.py
[2024-07-29T00:30:54.107+0000] {processor.py:183} INFO - Processing /opt/airflow/dags/airflow-dags/datalake/etl_products.py took 1.109 seconds
[2024-07-29T00:31:24.283+0000] {processor.py:161} INFO - Started process (PID=5381) to work on /opt/airflow/dags/airflow-dags/datalake/etl_products.py
[2024-07-29T00:31:24.287+0000] {processor.py:830} INFO - Processing file /opt/airflow/dags/airflow-dags/datalake/etl_products.py for tasks to queue
[2024-07-29T00:31:24.290+0000] {logging_mixin.py:188} INFO - [2024-07-29T00:31:24.289+0000] {dagbag.py:540} INFO - Filling up the DagBag from /opt/airflow/dags/airflow-dags/datalake/etl_products.py
[2024-07-29T00:31:25.331+0000] {logging_mixin.py:188} INFO - [2024-07-29T00:31:25.327+0000] {dagbag.py:350} ERROR - Failed to import: /opt/airflow/dags/airflow-dags/datalake/etl_products.py
Traceback (most recent call last):
  File "/home/airflow/.local/lib/python3.12/site-packages/airflow/models/dagbag.py", line 346, in parse
    loader.exec_module(new_module)
  File "<frozen importlib._bootstrap_external>", line 995, in exec_module
  File "<frozen importlib._bootstrap>", line 488, in _call_with_frames_removed
  File "/opt/airflow/dags/airflow-dags/datalake/etl_products.py", line 25, in <module>
    driver = webdriver.Chrome(executable_path=r'/opt/airflow/chromedriver', options=options)
             ^^^^^^^^^^^^^^^^^^^^^^^^^^^^^^^^^^^^^^^^^^^^^^^^^^^^^^^^^^^^^^^^^^^^^^^^^^^^^^^
  File "/home/airflow/.local/lib/python3.12/site-packages/selenium/webdriver/chrome/webdriver.py", line 73, in __init__
    self.service.start()
  File "/home/airflow/.local/lib/python3.12/site-packages/selenium/webdriver/common/service.py", line 98, in start
    self.assert_process_still_running()
  File "/home/airflow/.local/lib/python3.12/site-packages/selenium/webdriver/common/service.py", line 109, in assert_process_still_running
    raise WebDriverException(
selenium.common.exceptions.WebDriverException: Message: Service /opt/airflow/chromedriver unexpectedly exited. Status code was: 127
[2024-07-29T00:31:25.360+0000] {processor.py:842} WARNING - No viable dags retrieved from /opt/airflow/dags/airflow-dags/datalake/etl_products.py
[2024-07-29T00:31:25.375+0000] {processor.py:183} INFO - Processing /opt/airflow/dags/airflow-dags/datalake/etl_products.py took 1.097 seconds
[2024-07-29T00:31:55.595+0000] {processor.py:161} INFO - Started process (PID=5399) to work on /opt/airflow/dags/airflow-dags/datalake/etl_products.py
[2024-07-29T00:31:55.600+0000] {processor.py:830} INFO - Processing file /opt/airflow/dags/airflow-dags/datalake/etl_products.py for tasks to queue
[2024-07-29T00:31:55.601+0000] {logging_mixin.py:188} INFO - [2024-07-29T00:31:55.601+0000] {dagbag.py:540} INFO - Filling up the DagBag from /opt/airflow/dags/airflow-dags/datalake/etl_products.py
[2024-07-29T00:31:56.642+0000] {logging_mixin.py:188} INFO - [2024-07-29T00:31:56.641+0000] {dagbag.py:350} ERROR - Failed to import: /opt/airflow/dags/airflow-dags/datalake/etl_products.py
Traceback (most recent call last):
  File "/home/airflow/.local/lib/python3.12/site-packages/airflow/models/dagbag.py", line 346, in parse
    loader.exec_module(new_module)
  File "<frozen importlib._bootstrap_external>", line 995, in exec_module
  File "<frozen importlib._bootstrap>", line 488, in _call_with_frames_removed
  File "/opt/airflow/dags/airflow-dags/datalake/etl_products.py", line 25, in <module>
    driver = webdriver.Chrome(executable_path=r'/opt/airflow/chromedriver', options=options)
             ^^^^^^^^^^^^^^^^^^^^^^^^^^^^^^^^^^^^^^^^^^^^^^^^^^^^^^^^^^^^^^^^^^^^^^^^^^^^^^^
  File "/home/airflow/.local/lib/python3.12/site-packages/selenium/webdriver/chrome/webdriver.py", line 73, in __init__
    self.service.start()
  File "/home/airflow/.local/lib/python3.12/site-packages/selenium/webdriver/common/service.py", line 98, in start
    self.assert_process_still_running()
  File "/home/airflow/.local/lib/python3.12/site-packages/selenium/webdriver/common/service.py", line 109, in assert_process_still_running
    raise WebDriverException(
selenium.common.exceptions.WebDriverException: Message: Service /opt/airflow/chromedriver unexpectedly exited. Status code was: 127
[2024-07-29T00:31:56.669+0000] {processor.py:842} WARNING - No viable dags retrieved from /opt/airflow/dags/airflow-dags/datalake/etl_products.py
[2024-07-29T00:31:56.689+0000] {processor.py:183} INFO - Processing /opt/airflow/dags/airflow-dags/datalake/etl_products.py took 1.100 seconds
[2024-07-29T00:32:26.892+0000] {processor.py:161} INFO - Started process (PID=5416) to work on /opt/airflow/dags/airflow-dags/datalake/etl_products.py
[2024-07-29T00:32:26.897+0000] {processor.py:830} INFO - Processing file /opt/airflow/dags/airflow-dags/datalake/etl_products.py for tasks to queue
[2024-07-29T00:32:26.898+0000] {logging_mixin.py:188} INFO - [2024-07-29T00:32:26.898+0000] {dagbag.py:540} INFO - Filling up the DagBag from /opt/airflow/dags/airflow-dags/datalake/etl_products.py
[2024-07-29T00:32:27.933+0000] {logging_mixin.py:188} INFO - [2024-07-29T00:32:27.932+0000] {dagbag.py:350} ERROR - Failed to import: /opt/airflow/dags/airflow-dags/datalake/etl_products.py
Traceback (most recent call last):
  File "/home/airflow/.local/lib/python3.12/site-packages/airflow/models/dagbag.py", line 346, in parse
    loader.exec_module(new_module)
  File "<frozen importlib._bootstrap_external>", line 995, in exec_module
  File "<frozen importlib._bootstrap>", line 488, in _call_with_frames_removed
  File "/opt/airflow/dags/airflow-dags/datalake/etl_products.py", line 25, in <module>
    driver = webdriver.Chrome(executable_path=r'/opt/airflow/chromedriver', options=options)
             ^^^^^^^^^^^^^^^^^^^^^^^^^^^^^^^^^^^^^^^^^^^^^^^^^^^^^^^^^^^^^^^^^^^^^^^^^^^^^^^
  File "/home/airflow/.local/lib/python3.12/site-packages/selenium/webdriver/chrome/webdriver.py", line 73, in __init__
    self.service.start()
  File "/home/airflow/.local/lib/python3.12/site-packages/selenium/webdriver/common/service.py", line 98, in start
    self.assert_process_still_running()
  File "/home/airflow/.local/lib/python3.12/site-packages/selenium/webdriver/common/service.py", line 109, in assert_process_still_running
    raise WebDriverException(
selenium.common.exceptions.WebDriverException: Message: Service /opt/airflow/chromedriver unexpectedly exited. Status code was: 127
[2024-07-29T00:32:27.966+0000] {processor.py:842} WARNING - No viable dags retrieved from /opt/airflow/dags/airflow-dags/datalake/etl_products.py
[2024-07-29T00:32:27.981+0000] {processor.py:183} INFO - Processing /opt/airflow/dags/airflow-dags/datalake/etl_products.py took 1.095 seconds
[2024-07-29T00:32:58.154+0000] {processor.py:161} INFO - Started process (PID=5434) to work on /opt/airflow/dags/airflow-dags/datalake/etl_products.py
[2024-07-29T00:32:58.155+0000] {processor.py:830} INFO - Processing file /opt/airflow/dags/airflow-dags/datalake/etl_products.py for tasks to queue
[2024-07-29T00:32:58.156+0000] {logging_mixin.py:188} INFO - [2024-07-29T00:32:58.156+0000] {dagbag.py:540} INFO - Filling up the DagBag from /opt/airflow/dags/airflow-dags/datalake/etl_products.py
[2024-07-29T00:32:59.200+0000] {logging_mixin.py:188} INFO - [2024-07-29T00:32:59.198+0000] {dagbag.py:350} ERROR - Failed to import: /opt/airflow/dags/airflow-dags/datalake/etl_products.py
Traceback (most recent call last):
  File "/home/airflow/.local/lib/python3.12/site-packages/airflow/models/dagbag.py", line 346, in parse
    loader.exec_module(new_module)
  File "<frozen importlib._bootstrap_external>", line 995, in exec_module
  File "<frozen importlib._bootstrap>", line 488, in _call_with_frames_removed
  File "/opt/airflow/dags/airflow-dags/datalake/etl_products.py", line 25, in <module>
    driver = webdriver.Chrome(executable_path=r'/opt/airflow/chromedriver', options=options)
             ^^^^^^^^^^^^^^^^^^^^^^^^^^^^^^^^^^^^^^^^^^^^^^^^^^^^^^^^^^^^^^^^^^^^^^^^^^^^^^^
  File "/home/airflow/.local/lib/python3.12/site-packages/selenium/webdriver/chrome/webdriver.py", line 73, in __init__
    self.service.start()
  File "/home/airflow/.local/lib/python3.12/site-packages/selenium/webdriver/common/service.py", line 98, in start
    self.assert_process_still_running()
  File "/home/airflow/.local/lib/python3.12/site-packages/selenium/webdriver/common/service.py", line 109, in assert_process_still_running
    raise WebDriverException(
selenium.common.exceptions.WebDriverException: Message: Service /opt/airflow/chromedriver unexpectedly exited. Status code was: 127
[2024-07-29T00:32:59.223+0000] {processor.py:842} WARNING - No viable dags retrieved from /opt/airflow/dags/airflow-dags/datalake/etl_products.py
[2024-07-29T00:32:59.240+0000] {processor.py:183} INFO - Processing /opt/airflow/dags/airflow-dags/datalake/etl_products.py took 1.090 seconds
[2024-07-29T00:33:29.404+0000] {processor.py:161} INFO - Started process (PID=5452) to work on /opt/airflow/dags/airflow-dags/datalake/etl_products.py
[2024-07-29T00:33:29.405+0000] {processor.py:830} INFO - Processing file /opt/airflow/dags/airflow-dags/datalake/etl_products.py for tasks to queue
[2024-07-29T00:33:29.406+0000] {logging_mixin.py:188} INFO - [2024-07-29T00:33:29.406+0000] {dagbag.py:540} INFO - Filling up the DagBag from /opt/airflow/dags/airflow-dags/datalake/etl_products.py
[2024-07-29T00:33:30.443+0000] {logging_mixin.py:188} INFO - [2024-07-29T00:33:30.438+0000] {dagbag.py:350} ERROR - Failed to import: /opt/airflow/dags/airflow-dags/datalake/etl_products.py
Traceback (most recent call last):
  File "/home/airflow/.local/lib/python3.12/site-packages/airflow/models/dagbag.py", line 346, in parse
    loader.exec_module(new_module)
  File "<frozen importlib._bootstrap_external>", line 995, in exec_module
  File "<frozen importlib._bootstrap>", line 488, in _call_with_frames_removed
  File "/opt/airflow/dags/airflow-dags/datalake/etl_products.py", line 25, in <module>
    driver = webdriver.Chrome(executable_path=r'/opt/airflow/chromedriver', options=options)
             ^^^^^^^^^^^^^^^^^^^^^^^^^^^^^^^^^^^^^^^^^^^^^^^^^^^^^^^^^^^^^^^^^^^^^^^^^^^^^^^
  File "/home/airflow/.local/lib/python3.12/site-packages/selenium/webdriver/chrome/webdriver.py", line 73, in __init__
    self.service.start()
  File "/home/airflow/.local/lib/python3.12/site-packages/selenium/webdriver/common/service.py", line 98, in start
    self.assert_process_still_running()
  File "/home/airflow/.local/lib/python3.12/site-packages/selenium/webdriver/common/service.py", line 109, in assert_process_still_running
    raise WebDriverException(
selenium.common.exceptions.WebDriverException: Message: Service /opt/airflow/chromedriver unexpectedly exited. Status code was: 127
[2024-07-29T00:33:30.469+0000] {processor.py:842} WARNING - No viable dags retrieved from /opt/airflow/dags/airflow-dags/datalake/etl_products.py
[2024-07-29T00:33:30.482+0000] {processor.py:183} INFO - Processing /opt/airflow/dags/airflow-dags/datalake/etl_products.py took 1.082 seconds
[2024-07-29T00:34:00.692+0000] {processor.py:161} INFO - Started process (PID=5470) to work on /opt/airflow/dags/airflow-dags/datalake/etl_products.py
[2024-07-29T00:34:00.697+0000] {processor.py:830} INFO - Processing file /opt/airflow/dags/airflow-dags/datalake/etl_products.py for tasks to queue
[2024-07-29T00:34:00.699+0000] {logging_mixin.py:188} INFO - [2024-07-29T00:34:00.699+0000] {dagbag.py:540} INFO - Filling up the DagBag from /opt/airflow/dags/airflow-dags/datalake/etl_products.py
[2024-07-29T00:34:01.735+0000] {logging_mixin.py:188} INFO - [2024-07-29T00:34:01.732+0000] {dagbag.py:350} ERROR - Failed to import: /opt/airflow/dags/airflow-dags/datalake/etl_products.py
Traceback (most recent call last):
  File "/home/airflow/.local/lib/python3.12/site-packages/airflow/models/dagbag.py", line 346, in parse
    loader.exec_module(new_module)
  File "<frozen importlib._bootstrap_external>", line 995, in exec_module
  File "<frozen importlib._bootstrap>", line 488, in _call_with_frames_removed
  File "/opt/airflow/dags/airflow-dags/datalake/etl_products.py", line 25, in <module>
    driver = webdriver.Chrome(executable_path=r'/opt/airflow/chromedriver', options=options)
             ^^^^^^^^^^^^^^^^^^^^^^^^^^^^^^^^^^^^^^^^^^^^^^^^^^^^^^^^^^^^^^^^^^^^^^^^^^^^^^^
  File "/home/airflow/.local/lib/python3.12/site-packages/selenium/webdriver/chrome/webdriver.py", line 73, in __init__
    self.service.start()
  File "/home/airflow/.local/lib/python3.12/site-packages/selenium/webdriver/common/service.py", line 98, in start
    self.assert_process_still_running()
  File "/home/airflow/.local/lib/python3.12/site-packages/selenium/webdriver/common/service.py", line 109, in assert_process_still_running
    raise WebDriverException(
selenium.common.exceptions.WebDriverException: Message: Service /opt/airflow/chromedriver unexpectedly exited. Status code was: 127
[2024-07-29T00:34:01.773+0000] {processor.py:842} WARNING - No viable dags retrieved from /opt/airflow/dags/airflow-dags/datalake/etl_products.py
[2024-07-29T00:34:01.787+0000] {processor.py:183} INFO - Processing /opt/airflow/dags/airflow-dags/datalake/etl_products.py took 1.100 seconds
[2024-07-29T00:34:32.002+0000] {processor.py:161} INFO - Started process (PID=5494) to work on /opt/airflow/dags/airflow-dags/datalake/etl_products.py
[2024-07-29T00:34:32.007+0000] {processor.py:830} INFO - Processing file /opt/airflow/dags/airflow-dags/datalake/etl_products.py for tasks to queue
[2024-07-29T00:34:32.009+0000] {logging_mixin.py:188} INFO - [2024-07-29T00:34:32.009+0000] {dagbag.py:540} INFO - Filling up the DagBag from /opt/airflow/dags/airflow-dags/datalake/etl_products.py
[2024-07-29T00:34:33.046+0000] {logging_mixin.py:188} INFO - [2024-07-29T00:34:33.042+0000] {dagbag.py:350} ERROR - Failed to import: /opt/airflow/dags/airflow-dags/datalake/etl_products.py
Traceback (most recent call last):
  File "/home/airflow/.local/lib/python3.12/site-packages/airflow/models/dagbag.py", line 346, in parse
    loader.exec_module(new_module)
  File "<frozen importlib._bootstrap_external>", line 995, in exec_module
  File "<frozen importlib._bootstrap>", line 488, in _call_with_frames_removed
  File "/opt/airflow/dags/airflow-dags/datalake/etl_products.py", line 25, in <module>
    driver = webdriver.Chrome(executable_path=r'/opt/airflow/chromedriver', options=options)
             ^^^^^^^^^^^^^^^^^^^^^^^^^^^^^^^^^^^^^^^^^^^^^^^^^^^^^^^^^^^^^^^^^^^^^^^^^^^^^^^
  File "/home/airflow/.local/lib/python3.12/site-packages/selenium/webdriver/chrome/webdriver.py", line 73, in __init__
    self.service.start()
  File "/home/airflow/.local/lib/python3.12/site-packages/selenium/webdriver/common/service.py", line 98, in start
    self.assert_process_still_running()
  File "/home/airflow/.local/lib/python3.12/site-packages/selenium/webdriver/common/service.py", line 109, in assert_process_still_running
    raise WebDriverException(
selenium.common.exceptions.WebDriverException: Message: Service /opt/airflow/chromedriver unexpectedly exited. Status code was: 127
[2024-07-29T00:34:33.077+0000] {processor.py:842} WARNING - No viable dags retrieved from /opt/airflow/dags/airflow-dags/datalake/etl_products.py
[2024-07-29T00:34:33.092+0000] {processor.py:183} INFO - Processing /opt/airflow/dags/airflow-dags/datalake/etl_products.py took 1.098 seconds
[2024-07-29T00:35:03.312+0000] {processor.py:161} INFO - Started process (PID=5512) to work on /opt/airflow/dags/airflow-dags/datalake/etl_products.py
[2024-07-29T00:35:03.313+0000] {processor.py:830} INFO - Processing file /opt/airflow/dags/airflow-dags/datalake/etl_products.py for tasks to queue
[2024-07-29T00:35:03.315+0000] {logging_mixin.py:188} INFO - [2024-07-29T00:35:03.314+0000] {dagbag.py:540} INFO - Filling up the DagBag from /opt/airflow/dags/airflow-dags/datalake/etl_products.py
[2024-07-29T00:35:04.349+0000] {logging_mixin.py:188} INFO - [2024-07-29T00:35:04.345+0000] {dagbag.py:350} ERROR - Failed to import: /opt/airflow/dags/airflow-dags/datalake/etl_products.py
Traceback (most recent call last):
  File "/home/airflow/.local/lib/python3.12/site-packages/airflow/models/dagbag.py", line 346, in parse
    loader.exec_module(new_module)
  File "<frozen importlib._bootstrap_external>", line 995, in exec_module
  File "<frozen importlib._bootstrap>", line 488, in _call_with_frames_removed
  File "/opt/airflow/dags/airflow-dags/datalake/etl_products.py", line 25, in <module>
    driver = webdriver.Chrome(executable_path=r'/opt/airflow/chromedriver', options=options)
             ^^^^^^^^^^^^^^^^^^^^^^^^^^^^^^^^^^^^^^^^^^^^^^^^^^^^^^^^^^^^^^^^^^^^^^^^^^^^^^^
  File "/home/airflow/.local/lib/python3.12/site-packages/selenium/webdriver/chrome/webdriver.py", line 73, in __init__
    self.service.start()
  File "/home/airflow/.local/lib/python3.12/site-packages/selenium/webdriver/common/service.py", line 98, in start
    self.assert_process_still_running()
  File "/home/airflow/.local/lib/python3.12/site-packages/selenium/webdriver/common/service.py", line 109, in assert_process_still_running
    raise WebDriverException(
selenium.common.exceptions.WebDriverException: Message: Service /opt/airflow/chromedriver unexpectedly exited. Status code was: 127
[2024-07-29T00:35:04.389+0000] {processor.py:842} WARNING - No viable dags retrieved from /opt/airflow/dags/airflow-dags/datalake/etl_products.py
[2024-07-29T00:35:04.406+0000] {processor.py:183} INFO - Processing /opt/airflow/dags/airflow-dags/datalake/etl_products.py took 1.102 seconds
[2024-07-29T00:35:34.571+0000] {processor.py:161} INFO - Started process (PID=5531) to work on /opt/airflow/dags/airflow-dags/datalake/etl_products.py
[2024-07-29T00:35:34.575+0000] {processor.py:830} INFO - Processing file /opt/airflow/dags/airflow-dags/datalake/etl_products.py for tasks to queue
[2024-07-29T00:35:34.577+0000] {logging_mixin.py:188} INFO - [2024-07-29T00:35:34.576+0000] {dagbag.py:540} INFO - Filling up the DagBag from /opt/airflow/dags/airflow-dags/datalake/etl_products.py
[2024-07-29T00:35:35.610+0000] {logging_mixin.py:188} INFO - [2024-07-29T00:35:35.608+0000] {dagbag.py:350} ERROR - Failed to import: /opt/airflow/dags/airflow-dags/datalake/etl_products.py
Traceback (most recent call last):
  File "/home/airflow/.local/lib/python3.12/site-packages/airflow/models/dagbag.py", line 346, in parse
    loader.exec_module(new_module)
  File "<frozen importlib._bootstrap_external>", line 995, in exec_module
  File "<frozen importlib._bootstrap>", line 488, in _call_with_frames_removed
  File "/opt/airflow/dags/airflow-dags/datalake/etl_products.py", line 25, in <module>
    driver = webdriver.Chrome(executable_path=r'/opt/airflow/chromedriver', options=options)
             ^^^^^^^^^^^^^^^^^^^^^^^^^^^^^^^^^^^^^^^^^^^^^^^^^^^^^^^^^^^^^^^^^^^^^^^^^^^^^^^
  File "/home/airflow/.local/lib/python3.12/site-packages/selenium/webdriver/chrome/webdriver.py", line 73, in __init__
    self.service.start()
  File "/home/airflow/.local/lib/python3.12/site-packages/selenium/webdriver/common/service.py", line 98, in start
    self.assert_process_still_running()
  File "/home/airflow/.local/lib/python3.12/site-packages/selenium/webdriver/common/service.py", line 109, in assert_process_still_running
    raise WebDriverException(
selenium.common.exceptions.WebDriverException: Message: Service /opt/airflow/chromedriver unexpectedly exited. Status code was: 127
[2024-07-29T00:35:35.636+0000] {processor.py:842} WARNING - No viable dags retrieved from /opt/airflow/dags/airflow-dags/datalake/etl_products.py
[2024-07-29T00:35:35.656+0000] {processor.py:183} INFO - Processing /opt/airflow/dags/airflow-dags/datalake/etl_products.py took 1.089 seconds
[2024-07-29T00:36:05.870+0000] {processor.py:161} INFO - Started process (PID=5549) to work on /opt/airflow/dags/airflow-dags/datalake/etl_products.py
[2024-07-29T00:36:05.875+0000] {processor.py:830} INFO - Processing file /opt/airflow/dags/airflow-dags/datalake/etl_products.py for tasks to queue
[2024-07-29T00:36:05.879+0000] {logging_mixin.py:188} INFO - [2024-07-29T00:36:05.878+0000] {dagbag.py:540} INFO - Filling up the DagBag from /opt/airflow/dags/airflow-dags/datalake/etl_products.py
[2024-07-29T00:36:06.923+0000] {logging_mixin.py:188} INFO - [2024-07-29T00:36:06.919+0000] {dagbag.py:350} ERROR - Failed to import: /opt/airflow/dags/airflow-dags/datalake/etl_products.py
Traceback (most recent call last):
  File "/home/airflow/.local/lib/python3.12/site-packages/airflow/models/dagbag.py", line 346, in parse
    loader.exec_module(new_module)
  File "<frozen importlib._bootstrap_external>", line 995, in exec_module
  File "<frozen importlib._bootstrap>", line 488, in _call_with_frames_removed
  File "/opt/airflow/dags/airflow-dags/datalake/etl_products.py", line 25, in <module>
    driver = webdriver.Chrome(executable_path=r'/opt/airflow/chromedriver', options=options)
             ^^^^^^^^^^^^^^^^^^^^^^^^^^^^^^^^^^^^^^^^^^^^^^^^^^^^^^^^^^^^^^^^^^^^^^^^^^^^^^^
  File "/home/airflow/.local/lib/python3.12/site-packages/selenium/webdriver/chrome/webdriver.py", line 73, in __init__
    self.service.start()
  File "/home/airflow/.local/lib/python3.12/site-packages/selenium/webdriver/common/service.py", line 98, in start
    self.assert_process_still_running()
  File "/home/airflow/.local/lib/python3.12/site-packages/selenium/webdriver/common/service.py", line 109, in assert_process_still_running
    raise WebDriverException(
selenium.common.exceptions.WebDriverException: Message: Service /opt/airflow/chromedriver unexpectedly exited. Status code was: 127
[2024-07-29T00:36:06.955+0000] {processor.py:842} WARNING - No viable dags retrieved from /opt/airflow/dags/airflow-dags/datalake/etl_products.py
[2024-07-29T00:36:06.974+0000] {processor.py:183} INFO - Processing /opt/airflow/dags/airflow-dags/datalake/etl_products.py took 1.117 seconds
