[2024-08-25T19:10:00.678+0000] {local_task_job_runner.py:120} INFO - ::group::Pre task execution logs
[2024-08-25T19:10:00.695+0000] {taskinstance.py:2073} INFO - Dependencies all met for dep_context=non-requeueable deps ti=<TaskInstance: python_kubernetes_workflow_v2.task-2 scheduled__2024-08-25T19:09:00+00:00 [queued]>
[2024-08-25T19:10:00.703+0000] {taskinstance.py:2073} INFO - Dependencies all met for dep_context=requeueable deps ti=<TaskInstance: python_kubernetes_workflow_v2.task-2 scheduled__2024-08-25T19:09:00+00:00 [queued]>
[2024-08-25T19:10:00.704+0000] {taskinstance.py:2303} INFO - Starting attempt 1 of 2
[2024-08-25T19:10:00.717+0000] {taskinstance.py:2327} INFO - Executing <Task(KubernetesPodOperator): task-2> on 2024-08-25 19:09:00+00:00
[2024-08-25T19:10:00.725+0000] {logging_mixin.py:188} WARNING - /home/***/.local/lib/python3.12/site-packages/***/task/task_runner/standard_task_runner.py:61 DeprecationWarning: This process (pid=1096) is multi-threaded, use of fork() may lead to deadlocks in the child.
[2024-08-25T19:10:00.726+0000] {standard_task_runner.py:63} INFO - Started process 1098 to run task
[2024-08-25T19:10:00.724+0000] {standard_task_runner.py:90} INFO - Running: ['***', 'tasks', 'run', 'python_kubernetes_workflow_v2', 'task-2', 'scheduled__2024-08-25T19:09:00+00:00', '--job-id', '17', '--raw', '--subdir', 'DAGS_FOLDER/***-dags/testedag.py', '--cfg-path', '/tmp/tmpc2j4cl4_']
[2024-08-25T19:10:00.726+0000] {standard_task_runner.py:91} INFO - Job 17: Subtask task-2
[2024-08-25T19:10:00.906+0000] {task_command.py:426} INFO - Running <TaskInstance: python_kubernetes_workflow_v2.task-2 scheduled__2024-08-25T19:09:00+00:00 [running]> on host c30f0c2d1bf9
[2024-08-25T19:10:00.987+0000] {taskinstance.py:2644} INFO - Exporting env vars: AIRFLOW_CTX_DAG_EMAIL='***@example.com' AIRFLOW_CTX_DAG_OWNER='***' AIRFLOW_CTX_DAG_ID='python_kubernetes_workflow_v2' AIRFLOW_CTX_TASK_ID='task-2' AIRFLOW_CTX_EXECUTION_DATE='2024-08-25T19:09:00+00:00' AIRFLOW_CTX_TRY_NUMBER='1' AIRFLOW_CTX_DAG_RUN_ID='scheduled__2024-08-25T19:09:00+00:00'
[2024-08-25T19:10:00.987+0000] {taskinstance.py:430} INFO - ::endgroup::
[2024-08-25T19:10:00.990+0000] {logging_mixin.py:188} WARNING - /home/***/.local/lib/python3.12/site-packages/***/providers/cncf/kubernetes/operators/pod.py:1038 AirflowProviderDeprecationWarning: This function is deprecated. Please use `add_unique_suffix`.
[2024-08-25T19:10:00.991+0000] {pod.py:1057} INFO - Building pod task-2-pyrq1dg9 with labels: {'dag_id': 'python_kubernetes_workflow_v2', 'task_id': 'task-2', 'run_id': 'scheduled__2024-08-25T1909000000-afc7790e5', 'kubernetes_pod_operator': 'True', 'try_number': '1'}
[2024-08-25T19:10:01.012+0000] {connectionpool.py:824} WARNING - Retrying (Retry(total=2, connect=None, read=None, redirect=None, status=None)) after connection broken by 'NewConnectionError('<urllib3.connection.HTTPSConnection object at 0x7b460a94b500>: Failed to establish a new connection: [Errno 111] Connection refused')': /api/v1/namespaces/***/pods?labelSelector=dag_id%3Dpython_kubernetes_workflow_v2%2Cfoo%3Dbar%2Ckubernetes_pod_operator%3DTrue%2Crun_id%3Dscheduled__2024-08-25T1909000000-afc7790e5%2Ctask_id%3Dtask-2%2Calready_checked%21%3DTrue%2C%21***-worker
[2024-08-25T19:10:01.012+0000] {connectionpool.py:824} WARNING - Retrying (Retry(total=1, connect=None, read=None, redirect=None, status=None)) after connection broken by 'NewConnectionError('<urllib3.connection.HTTPSConnection object at 0x7b460a7a5520>: Failed to establish a new connection: [Errno 111] Connection refused')': /api/v1/namespaces/***/pods?labelSelector=dag_id%3Dpython_kubernetes_workflow_v2%2Cfoo%3Dbar%2Ckubernetes_pod_operator%3DTrue%2Crun_id%3Dscheduled__2024-08-25T1909000000-afc7790e5%2Ctask_id%3Dtask-2%2Calready_checked%21%3DTrue%2C%21***-worker
[2024-08-25T19:10:01.013+0000] {connectionpool.py:824} WARNING - Retrying (Retry(total=0, connect=None, read=None, redirect=None, status=None)) after connection broken by 'NewConnectionError('<urllib3.connection.HTTPSConnection object at 0x7b460a6a4d10>: Failed to establish a new connection: [Errno 111] Connection refused')': /api/v1/namespaces/***/pods?labelSelector=dag_id%3Dpython_kubernetes_workflow_v2%2Cfoo%3Dbar%2Ckubernetes_pod_operator%3DTrue%2Crun_id%3Dscheduled__2024-08-25T1909000000-afc7790e5%2Ctask_id%3Dtask-2%2Calready_checked%21%3DTrue%2C%21***-worker
[2024-08-25T19:10:01.013+0000] {taskinstance.py:441} INFO - ::group::Post task execution logs
[2024-08-25T19:10:01.014+0000] {taskinstance.py:2890} ERROR - Task failed with exception
Traceback (most recent call last):
  File "/home/airflow/.local/lib/python3.12/site-packages/urllib3/connection.py", line 174, in _new_conn
    conn = connection.create_connection(
           ^^^^^^^^^^^^^^^^^^^^^^^^^^^^^
  File "/home/airflow/.local/lib/python3.12/site-packages/urllib3/util/connection.py", line 95, in create_connection
    raise err
  File "/home/airflow/.local/lib/python3.12/site-packages/urllib3/util/connection.py", line 85, in create_connection
    sock.connect(sa)
ConnectionRefusedError: [Errno 111] Connection refused

During handling of the above exception, another exception occurred:

Traceback (most recent call last):
  File "/home/airflow/.local/lib/python3.12/site-packages/urllib3/connectionpool.py", line 715, in urlopen
    httplib_response = self._make_request(
                       ^^^^^^^^^^^^^^^^^^^
  File "/home/airflow/.local/lib/python3.12/site-packages/urllib3/connectionpool.py", line 404, in _make_request
    self._validate_conn(conn)
  File "/home/airflow/.local/lib/python3.12/site-packages/urllib3/connectionpool.py", line 1058, in _validate_conn
    conn.connect()
  File "/home/airflow/.local/lib/python3.12/site-packages/urllib3/connection.py", line 363, in connect
    self.sock = conn = self._new_conn()
                       ^^^^^^^^^^^^^^^^
  File "/home/airflow/.local/lib/python3.12/site-packages/urllib3/connection.py", line 186, in _new_conn
    raise NewConnectionError(
urllib3.exceptions.NewConnectionError: <urllib3.connection.HTTPSConnection object at 0x7b460a6a5d30>: Failed to establish a new connection: [Errno 111] Connection refused

During handling of the above exception, another exception occurred:

Traceback (most recent call last):
  File "/home/airflow/.local/lib/python3.12/site-packages/airflow/models/taskinstance.py", line 465, in _execute_task
    result = _execute_callable(context=context, **execute_callable_kwargs)
             ^^^^^^^^^^^^^^^^^^^^^^^^^^^^^^^^^^^^^^^^^^^^^^^^^^^^^^^^^^^^^
  File "/home/airflow/.local/lib/python3.12/site-packages/airflow/models/taskinstance.py", line 432, in _execute_callable
    return execute_callable(context=context, **execute_callable_kwargs)
           ^^^^^^^^^^^^^^^^^^^^^^^^^^^^^^^^^^^^^^^^^^^^^^^^^^^^^^^^^^^^
  File "/home/airflow/.local/lib/python3.12/site-packages/airflow/models/baseoperator.py", line 400, in wrapper
    return func(self, *args, **kwargs)
           ^^^^^^^^^^^^^^^^^^^^^^^^^^^
  File "/home/airflow/.local/lib/python3.12/site-packages/airflow/providers/cncf/kubernetes/operators/pod.py", line 570, in execute
    return self.execute_sync(context)
           ^^^^^^^^^^^^^^^^^^^^^^^^^^
  File "/home/airflow/.local/lib/python3.12/site-packages/airflow/providers/cncf/kubernetes/operators/pod.py", line 578, in execute_sync
    self.pod = self.get_or_create_pod(  # must set `self.pod` for `on_kill`
               ^^^^^^^^^^^^^^^^^^^^^^^^^^^^^^^^^^^^^^^^^^^^^^^^^^^^^^^^^^^^
  File "/home/airflow/.local/lib/python3.12/site-packages/airflow/providers/cncf/kubernetes/operators/pod.py", line 533, in get_or_create_pod
    pod = self.find_pod(self.namespace or pod_request_obj.metadata.namespace, context=context)
          ^^^^^^^^^^^^^^^^^^^^^^^^^^^^^^^^^^^^^^^^^^^^^^^^^^^^^^^^^^^^^^^^^^^^^^^^^^^^^^^^^^^^
  File "/home/airflow/.local/lib/python3.12/site-packages/airflow/providers/cncf/kubernetes/operators/pod.py", line 515, in find_pod
    pod_list = self.client.list_namespaced_pod(
               ^^^^^^^^^^^^^^^^^^^^^^^^^^^^^^^^
  File "/home/airflow/.local/lib/python3.12/site-packages/kubernetes/client/api/core_v1_api.py", line 15823, in list_namespaced_pod
    return self.list_namespaced_pod_with_http_info(namespace, **kwargs)  # noqa: E501
           ^^^^^^^^^^^^^^^^^^^^^^^^^^^^^^^^^^^^^^^^^^^^^^^^^^^^^^^^^^^^
  File "/home/airflow/.local/lib/python3.12/site-packages/kubernetes/client/api/core_v1_api.py", line 15942, in list_namespaced_pod_with_http_info
    return self.api_client.call_api(
           ^^^^^^^^^^^^^^^^^^^^^^^^^
  File "/home/airflow/.local/lib/python3.12/site-packages/kubernetes/client/api_client.py", line 348, in call_api
    return self.__call_api(resource_path, method,
           ^^^^^^^^^^^^^^^^^^^^^^^^^^^^^^^^^^^^^^
  File "/home/airflow/.local/lib/python3.12/site-packages/kubernetes/client/api_client.py", line 180, in __call_api
    response_data = self.request(
                    ^^^^^^^^^^^^^
  File "/home/airflow/.local/lib/python3.12/site-packages/kubernetes/client/api_client.py", line 373, in request
    return self.rest_client.GET(url,
           ^^^^^^^^^^^^^^^^^^^^^^^^^
  File "/home/airflow/.local/lib/python3.12/site-packages/kubernetes/client/rest.py", line 244, in GET
    return self.request("GET", url,
           ^^^^^^^^^^^^^^^^^^^^^^^^
  File "/home/airflow/.local/lib/python3.12/site-packages/kubernetes/client/rest.py", line 217, in request
    r = self.pool_manager.request(method, url,
        ^^^^^^^^^^^^^^^^^^^^^^^^^^^^^^^^^^^^^^
  File "/home/airflow/.local/lib/python3.12/site-packages/urllib3/request.py", line 77, in request
    return self.request_encode_url(
           ^^^^^^^^^^^^^^^^^^^^^^^^
  File "/home/airflow/.local/lib/python3.12/site-packages/urllib3/request.py", line 99, in request_encode_url
    return self.urlopen(method, url, **extra_kw)
           ^^^^^^^^^^^^^^^^^^^^^^^^^^^^^^^^^^^^^
  File "/home/airflow/.local/lib/python3.12/site-packages/urllib3/poolmanager.py", line 376, in urlopen
    response = conn.urlopen(method, u.request_uri, **kw)
               ^^^^^^^^^^^^^^^^^^^^^^^^^^^^^^^^^^^^^^^^^
  File "/home/airflow/.local/lib/python3.12/site-packages/urllib3/connectionpool.py", line 827, in urlopen
    return self.urlopen(
           ^^^^^^^^^^^^^
  File "/home/airflow/.local/lib/python3.12/site-packages/urllib3/connectionpool.py", line 827, in urlopen
    return self.urlopen(
           ^^^^^^^^^^^^^
  File "/home/airflow/.local/lib/python3.12/site-packages/urllib3/connectionpool.py", line 827, in urlopen
    return self.urlopen(
           ^^^^^^^^^^^^^
  File "/home/airflow/.local/lib/python3.12/site-packages/urllib3/connectionpool.py", line 799, in urlopen
    retries = retries.increment(
              ^^^^^^^^^^^^^^^^^^
  File "/home/airflow/.local/lib/python3.12/site-packages/urllib3/util/retry.py", line 592, in increment
    raise MaxRetryError(_pool, url, error or ResponseError(cause))
urllib3.exceptions.MaxRetryError: HTTPSConnectionPool(host='127.0.0.1', port=39521): Max retries exceeded with url: /api/v1/namespaces/***/pods?labelSelector=dag_id%3Dpython_kubernetes_workflow_v2%2Cfoo%3Dbar%2Ckubernetes_pod_operator%3DTrue%2Crun_id%3Dscheduled__2024-08-25T1909000000-afc7790e5%2Ctask_id%3Dtask-2%2Calready_checked%21%3DTrue%2C%21***-worker (Caused by NewConnectionError('<urllib3.connection.HTTPSConnection object at 0x7b460a6a5d30>: Failed to establish a new connection: [Errno 111] Connection refused'))
[2024-08-25T19:10:01.027+0000] {taskinstance.py:1205} INFO - Marking task as UP_FOR_RETRY. dag_id=python_kubernetes_workflow_v2, task_id=task-2, execution_date=20240825T190900, start_date=20240825T191000, end_date=20240825T191001
[2024-08-25T19:10:01.039+0000] {standard_task_runner.py:110} ERROR - Failed to execute job 17 for task task-2 (HTTPSConnectionPool(host='127.0.0.1', port=39521): Max retries exceeded with url: /api/v1/namespaces/***/pods?labelSelector=dag_id%3Dpython_kubernetes_workflow_v2%2Cfoo%3Dbar%2Ckubernetes_pod_operator%3DTrue%2Crun_id%3Dscheduled__2024-08-25T1909000000-afc7790e5%2Ctask_id%3Dtask-2%2Calready_checked%21%3DTrue%2C%21***-worker (Caused by NewConnectionError('<urllib3.connection.HTTPSConnection object at 0x7b460a6a5d30>: Failed to establish a new connection: [Errno 111] Connection refused')); 1098)
[2024-08-25T19:10:01.059+0000] {local_task_job_runner.py:240} INFO - Task exited with return code 1
[2024-08-25T19:10:01.231+0000] {taskinstance.py:3482} INFO - 0 downstream tasks scheduled from follow-on schedule check
[2024-08-25T19:10:01.233+0000] {local_task_job_runner.py:222} INFO - ::endgroup::
